Workbook

Sheet (直掃)RX Mapping
B1: 1 | C1: 2 | D1: 3 | E1: 4 | F1: 5 | G1: 6 | H1: 7 | I1: 8 | J1: 9 | K1: 10 | L1: 11 | M1: 12 | N1: 13 | O1: 14 | P1: 15 | Q1: 16 | R1: 17 | S1: 18 | T1: 19 | U1: 20 | V1: 21 | W1: 22 | X1: 23 | Y1: 24 | Z1: 25 | AA1: 26 | AB1: 27 | AC1: 28 | AD1: 29 | AE1: 30 | AF1: 31 | AG1: 32 | AH1: 33 | AI1: 34 | AJ1: 35 | AK1: 36 | AL1: 37 | AM1: 38 | AN1: 39 | AO1: 40 | AP1: 41 | AQ1: 42 | AR1: 43 | AS1: 44 | AT1: 45 | AU1: 46 | AV1: 47 | AW1: 48 | AX1: 49 | AY1: 50 | AZ1: 51 | BA1: 52 | BB1: 53 | BC1: 54 | BD1: 55 | BE1: 56 | BF1: 57 | BG1: 58 | BH1: 59 | BI1: 60
A2: 1 | B2: 960 | C2: 930 | D2: 900 | E2: 840 | F2: 810 | G2: 780 | H2: 720 | I2: 690 | J2: 660 | K2: 630 | L2: 600 | M2: 570 | N2: 540 | O2: 510 | P2: 480 | Q2: 450 | R2: 420 | S2: 390 | T2: 360 | U2: 330 | V2: 300 | W2: 270 | X2: 210 | Y2: 180 | Z2: 150 | AA2: 90 | AB2: 60 | AC2: 30
A3: 2 | B3: 959 | C3: 929 | D3: 899 | E3: 839 | F3: 809 | G3: 779 | H3: 719 | I3: 689 | J3: 659 | K3: 629 | L3: 599 | M3: 569 | N3: 539 | O3: 509 | P3: 479 | Q3: 449 | R3: 419 | S3: 389 | T3: 359 | U3: 329 | V3: 299 | W3: 269 | X3: 209 | Y3: 179 | Z3: 149 | AA3: 89 | AB3: 59 | AC3: 29
A4: 3 | B4: 958 | C4: 928 | D4: 898 | E4: 838 | F4: 808 | G4: 778 | H4: 718 | I4: 688 | J4: 658 | K4: 628 | L4: 598 | M4: 568 | N4: 538 | O4: 508 | P4: 478 | Q4: 448 | R4: 418 | S4: 388 | T4: 358 | U4: 328 | V4: 298 | W4: 268 | X4: 208 | Y4: 178 | Z4: 148 | AA4: 88 | AB4: 58 | AC4: 28
A5: 4 | B5: 957 | C5: 927 | D5: 897 | E5: 837 | F5: 807 | G5: 777 | H5: 717 | I5: 687 | J5: 657 | K5: 627 | L5: 597 | M5: 567 | N5: 537 | O5: 507 | P5: 477 | Q5: 447 | R5: 417 | S5: 387 | T5: 357 | U5: 327 | V5: 297 | W5: 267 | X5: 207 | Y5: 177 | Z5: 147 | AA5: 87 | AB5: 57 | AC5: 27
A6: 5 | B6: 956 | C6: 926 | D6: 896 | E6: 836 | F6: 806 | G6: 776 | H6: 716 | I6: 686 | J6: 656 | K6: 626 | L6: 596 | M6: 566 | N6: 536 | O6: 506 | P6: 476 | Q6: 446 | R6: 416 | S6: 386 | T6: 356 | U6: 326 | V6: 296 | W6: 266 | X6: 206 | Y6: 176 | Z6: 146 | AA6: 86 | AB6: 56 | AC6: 26
A7: 6 | B7: 955 | C7: 925 | D7: 895 | E7: 835 | F7: 805 | G7: 775 | H7: 715 | I7: 685 | J7: 655 | K7: 625 | L7: 595 | M7: 565 | N7: 535 | O7: 505 | P7: 475 | Q7: 445 | R7: 415 | S7: 385 | T7: 355 | U7: 325 | V7: 295 | W7: 265 | X7: 205 | Y7: 175 | Z7: 145 | AA7: 85 | AB7: 55 | AC7: 25
A8: 7 | B8: 954 | C8: 924 | D8: 894 | E8: 834 | F8: 804 | G8: 774 | H8: 714 | I8: 684 | J8: 654 | K8: 624 | L8: 594 | M8: 564 | N8: 534 | O8: 504 | P8: 474 | Q8: 444 | R8: 414 | S8: 384 | T8: 354 | U8: 324 | V8: 294 | W8: 264 | X8: 204 | Y8: 174 | Z8: 144 | AA8: 84 | AB8: 54 | AC8: 24
A9: 8 | B9: 953 | C9: 923 | D9: 893 | E9: 833 | F9: 803 | G9: 773 | H9: 713 | I9: 683 | J9: 653 | K9: 623 | L9: 593 | M9: 563 | N9: 533 | O9: 503 | P9: 473 | Q9: 443 | R9: 413 | S9: 383 | T9: 353 | U9: 323 | V9: 293 | W9: 263 | X9: 203 | Y9: 173 | Z9: 143 | AA9: 83 | AB9: 53 | AC9: 23
A10: 9 | B10: 952 | C10: 922 | D10: 892 | E10: 832 | F10: 802 | G10: 772 | H10: 712 | I10: 682 | J10: 652 | K10: 622 | L10: 592 | M10: 562 | N10: 532 | O10: 502 | P10: 472 | Q10: 442 | R10: 412 | S10: 382 | T10: 352 | U10: 322 | V10: 292 | W10: 262 | X10: 202 | Y10: 172 | Z10: 142 | AA10: 82 | AB10: 52 | AC10: 22
A11: 10 | B11: 951 | C11: 921 | D11: 891 | E11: 831 | F11: 801 | G11: 771 | H11: 711 | I11: 681 | J11: 651 | K11: 621 | L11: 591 | M11: 561 | N11: 531 | O11: 501 | P11: 471 | Q11: 441 | R11: 411 | S11: 381 | T11: 351 | U11: 321 | V11: 291 | W11: 261 | X11: 201 | Y11: 171 | Z11: 141 | AA11: 81 | AB11: 51 | AC11: 21
A12: 11 | B12: 950 | C12: 920 | D12: 890 | E12: 830 | F12: 800 | G12: 770 | H12: 710 | I12: 680 | J12: 650 | K12: 620 | L12: 590 | M12: 560 | N12: 530 | O12: 500 | P12: 470 | Q12: 440 | R12: 410 | S12: 380 | T12: 350 | U12: 320 | V12: 290 | W12: 260 | X12: 200 | Y12: 170 | Z12: 140 | AA12: 80 | AB12: 50 | AC12: 20
A13: 12 | B13: 949 | C13: 919 | D13: 889 | E13: 829 | F13: 799 | G13: 769 | H13: 709 | I13: 679 | J13: 649 | K13: 619 | L13: 589 | M13: 559 | N13: 529 | O13: 499 | P13: 469 | Q13: 439 | R13: 409 | S13: 379 | T13: 349 | U13: 319 | V13: 289 | W13: 259 | X13: 199 | Y13: 169 | Z13: 139 | AA13: 79 | AB13: 49 | AC13: 19
... A31: 30 | B31: 931 | C31: 901 | D31: 871 | E31: 811 | F31: 781 | G31: 751 | H31: 691 | I31: 661 | J31: 631 | K31: 601 | L31: 571 | M31: 541 | N31: 511 | O31: 481 | P31: 451 | Q31: 421 | R31: 391 | S31: 361 | T31: 331 | U31: 301 | V31: 271 | W31: 241 | X31: 181 | Y31: 151 | Z31: 121 | AA31: 61 | AB31: 31 | AC31: 1
A32: 31
A33: 32
A34: 33
A35: 34
A36: 35
A37: 36
A38: 37
A39: 38
A40: 39
A41: 40
A42: 41
A43: 42
... A61: 60

Sheet (直掃)Change to adc mapping 
B1: 1 | C1: 2 | D1: 3 | E1: 4 | F1: 5 | G1: 6 | H1: 7 | I1: 8 | J1: 9 | K1: 10 | L1: 11 | M1: 12 | N1: 13 | O1: 14 | P1: 15 | Q1: 16 | R1: 17 | S1: 18 | T1: 19 | U1: 20 | V1: 21 | W1: 22 | X1: 23 | Y1: 24 | Z1: 25 | AA1: 26 | AB1: 27 | AC1: 28 | AD1: 29 | AE1: 30 | AF1: 31 | AG1: 32 | AH1: 33 | AI1: 34 | AJ1: 35 | AK1: 36 | AL1: 37 | AM1: 38 | AN1: 39 | AO1: 40 | AP1: 41 | AQ1: 42 | AR1: 43 | AS1: 44 | AT1: 45 | AU1: 46 | AV1: 47 | AW1: 48 | AX1: 49 | AY1: 50 | AZ1: 51 | BA1: 52 | BB1: 53 | BC1: 54 | BD1: 55 | BE1: 56 | BF1: 57 | BG1: 58 | BH1: 59 | BI1: 60
A2: 1 | B2: =IF( (AND('(直掃)RX Mapping'!B2>=0,'(直掃)RX Mapping'!B2<=480)), (MOD('(直掃)RX Mapping'!B2,120)-1), IF( (AND('(直掃)RX Mapping'!B2>=480,'(直掃)RX Mapping'!B2<=960)), IF(MOD('(直掃)RX Mapping'!B2,120)=0, 120, 240-MOD('(直掃)RX Mapping'!B2,120)),9999))+IF(AND(MOD('(直掃)RX Mapping'!B2,120)=0, '(直掃)RX Mapping'!B2 <= 480, '(直掃)RX Mapping'!B2 > 0), 120) -> 120 | C2: =IF( (AND('(直掃)RX Mapping'!C2>=0,'(直掃)RX Mapping'!C2<=480)), (MOD('(直掃)RX Mapping'!C2,120)-1), IF( (AND('(直掃)RX Mapping'!C2>=480,'(直掃)RX Mapping'!C2<=960)), IF(MOD('(直掃)RX Mapping'!C2,120)=0, 120, 240-MOD('(直掃)RX Mapping'!C2,120)),9999))+IF(AND(MOD('(直掃)RX Mapping'!C2,120)=0, '(直掃)RX Mapping'!C2 <= 480, '(直掃)RX Mapping'!C2 > 0), 120) -> 150 | D2: =IF( (AND('(直掃)RX Mapping'!D2>=0,'(直掃)RX Mapping'!D2<=480)), (MOD('(直掃)RX Mapping'!D2,120)-1), IF( (AND('(直掃)RX Mapping'!D2>=480,'(直掃)RX Mapping'!D2<=960)), IF(MOD('(直掃)RX Mapping'!D2,120)=0, 120, 240-MOD('(直掃)RX Mapping'!D2,120)),9999))+IF(AND(MOD('(直掃)RX Mapping'!D2,120)=0, '(直掃)RX Mapping'!D2 <= 480, '(直掃)RX Mapping'!D2 > 0), 120) -> 180 | E2: =IF( (AND('(直掃)RX Mapping'!E2>=0,'(直掃)RX Mapping'!E2<=480)), (MOD('(直掃)RX Mapping'!E2,120)-1), IF( (AND('(直掃)RX Mapping'!E2>=480,'(直掃)RX Mapping'!E2<=960)), IF(MOD('(直掃)RX Mapping'!E2,120)=0, 120, 240-MOD('(直掃)RX Mapping'!E2,120)),9999))+IF(AND(MOD('(直掃)RX Mapping'!E2,120)=0, '(直掃)RX Mapping'!E2 <= 480, '(直掃)RX Mapping'!E2 > 0), 120) -> 120 | F2: =IF( (AND('(直掃)RX Mapping'!F2>=0,'(直掃)RX Mapping'!F2<=480)), (MOD('(直掃)RX Mapping'!F2,120)-1), IF( (AND('(直掃)RX Mapping'!F2>=480,'(直掃)RX Mapping'!F2<=960)), IF(MOD('(直掃)RX Mapping'!F2,120)=0, 120, 240-MOD('(直掃)RX Mapping'!F2,120)),9999))+IF(AND(MOD('(直掃)RX Mapping'!F2,120)=0, '(直掃)RX Mapping'!F2 <= 480, '(直掃)RX Mapping'!F2 > 0), 120) -> 150 | G2: =IF( (AND('(直掃)RX Mapping'!G2>=0,'(直掃)RX Mapping'!G2<=480)), (MOD('(直掃)RX Mapping'!G2,120)-1), IF( (AND('(直掃)RX Mapping'!G2>=480,'(直掃)RX Mapping'!G2<=960)), IF(MOD('(直掃)RX Mapping'!G2,120)=0, 120, 240-MOD('(直掃)RX Mapping'!G2,120)),9999))+IF(AND(MOD('(直掃)RX Mapping'!G2,120)=0, '(直掃)RX Mapping'!G2 <= 480, '(直掃)RX Mapping'!G2 > 0), 120) -> 180 | H2: =IF( (AND('(直掃)RX Mapping'!H2>=0,'(直掃)RX Mapping'!H2<=480)), (MOD('(直掃)RX Mapping'!H2,120)-1), IF( (AND('(直掃)RX Mapping'!H2>=480,'(直掃)RX Mapping'!H2<=960)), IF(MOD('(直掃)RX Mapping'!H2,120)=0, 120, 240-MOD('(直掃)RX Mapping'!H2,120)),9999))+IF(AND(MOD('(直掃)RX Mapping'!H2,120)=0, '(直掃)RX Mapping'!H2 <= 480, '(直掃)RX Mapping'!H2 > 0), 120) -> 120 | I2: =IF( (AND('(直掃)RX Mapping'!I2>=0,'(直掃)RX Mapping'!I2<=480)), (MOD('(直掃)RX Mapping'!I2,120)-1), IF( (AND('(直掃)RX Mapping'!I2>=480,'(直掃)RX Mapping'!I2<=960)), IF(MOD('(直掃)RX Mapping'!I2,120)=0, 120, 240-MOD('(直掃)RX Mapping'!I2,120)),9999))+IF(AND(MOD('(直掃)RX Mapping'!I2,120)=0, '(直掃)RX Mapping'!I2 <= 480, '(直掃)RX Mapping'!I2 > 0), 120) -> 150 | ... AS2: =IF( (AND('(直掃)RX Mapping'!AS2>=0,'(直掃)RX Mapping'!AS2<=480)), (MOD('(直掃)RX Mapping'!AS2,120)-1), IF( (AND('(直掃)RX Mapping'!AS2>=480,'(直掃)RX Mapping'!AS2<=960)), IF(MOD('(直掃)RX Mapping'!AS2,120)=0, 120, 240-MOD('(直掃)RX Mapping'!AS2,120)),9999))+IF(AND(MOD('(直掃)RX Mapping'!AS2,120)=0, '(直掃)RX Mapping'!AS2 <= 480, '(直掃)RX Mapping'!AS2 > 0), 120) -> -1 | AT2: =IF(AND('(橫掃)RX Mapping'!AT2>=1,'(橫掃)RX Mapping'!AT2<=120), ('(橫掃)RX Mapping'!AT2-1),IF(AND('(橫掃)RX Mapping'!AT2>=121,'(橫掃)RX Mapping'!AT2<=240), (-1)*('(橫掃)RX Mapping'!AT2-240),IF(AND('(橫掃)RX Mapping'!AT2>=241,'(橫掃)RX Mapping'!AT2<=360), ('(橫掃)RX Mapping'!AT2-241),IF(AND('(橫掃)RX Mapping'!AT2>=361,'(橫掃)RX Mapping'!AT2<=480), (-1)*('(橫掃)RX Mapping'!AT2-480),IF(AND('(橫掃)RX Mapping'!AT2>=481,'(橫掃)RX Mapping'!AT2<=600), ('(橫掃)RX Mapping'!AT2-361),IF(AND('(橫掃)RX Mapping'!AT2>=601,'(橫掃)RX Mapping'!AT2<=720), (-1)*('(橫掃)RX Mapping'!AT2-720)+120,IF(AND('(橫掃)RX Mapping'!AT2>=721,'(橫掃)RX Mapping'!AT2<=840), ('(橫掃)RX Mapping'!AT2-601),IF(AND('(橫掃)RX Mapping'!AT2>=841,'(橫掃)RX Mapping'!AT2<=960), (-1)*('(橫掃)RX Mapping'!AT2-960)+120,9999)))))))) -> 9999 | AU2: =IF(AND('(橫掃)RX Mapping'!AU2>=1,'(橫掃)RX Mapping'!AU2<=120), ('(橫掃)RX Mapping'!AU2-1),IF(AND('(橫掃)RX Mapping'!AU2>=121,'(橫掃)RX Mapping'!AU2<=240), (-1)*('(橫掃)RX Mapping'!AU2-240),IF(AND('(橫掃)RX Mapping'!AU2>=241,'(橫掃)RX Mapping'!AU2<=360), ('(橫掃)RX Mapping'!AU2-241),IF(AND('(橫掃)RX Mapping'!AU2>=361,'(橫掃)RX Mapping'!AU2<=480), (-1)*('(橫掃)RX Mapping'!AU2-480),IF(AND('(橫掃)RX Mapping'!AU2>=481,'(橫掃)RX Mapping'!AU2<=600), ('(橫掃)RX Mapping'!AU2-361),IF(AND('(橫掃)RX Mapping'!AU2>=601,'(橫掃)RX Mapping'!AU2<=720), (-1)*('(橫掃)RX Mapping'!AU2-720)+120,IF(AND('(橫掃)RX Mapping'!AU2>=721,'(橫掃)RX Mapping'!AU2<=840), ('(橫掃)RX Mapping'!AU2-601),IF(AND('(橫掃)RX Mapping'!AU2>=841,'(橫掃)RX Mapping'!AU2<=960), (-1)*('(橫掃)RX Mapping'!AU2-960)+120,9999)))))))) -> 9999 | AV2: =IF(AND('(橫掃)RX Mapping'!AV2>=1,'(橫掃)RX Mapping'!AV2<=120), ('(橫掃)RX Mapping'!AV2-1),IF(AND('(橫掃)RX Mapping'!AV2>=121,'(橫掃)RX Mapping'!AV2<=240), (-1)*('(橫掃)RX Mapping'!AV2-240),IF(AND('(橫掃)RX Mapping'!AV2>=241,'(橫掃)RX Mapping'!AV2<=360), ('(橫掃)RX Mapping'!AV2-241),IF(AND('(橫掃)RX Mapping'!AV2>=361,'(橫掃)RX Mapping'!AV2<=480), (-1)*('(橫掃)RX Mapping'!AV2-480),IF(AND('(橫掃)RX Mapping'!AV2>=481,'(橫掃)RX Mapping'!AV2<=600), ('(橫掃)RX Mapping'!AV2-361),IF(AND('(橫掃)RX Mapping'!AV2>=601,'(橫掃)RX Mapping'!AV2<=720), (-1)*('(橫掃)RX Mapping'!AV2-720)+120,IF(AND('(橫掃)RX Mapping'!AV2>=721,'(橫掃)RX Mapping'!AV2<=840), ('(橫掃)RX Mapping'!AV2-601),IF(AND('(橫掃)RX Mapping'!AV2>=841,'(橫掃)RX Mapping'!AV2<=960), (-1)*('(橫掃)RX Mapping'!AV2-960)+120,9999)))))))) -> 9999 | AW2: =IF(AND('(橫掃)RX Mapping'!AW2>=1,'(橫掃)RX Mapping'!AW2<=120), ('(橫掃)RX Mapping'!AW2-1),IF(AND('(橫掃)RX Mapping'!AW2>=121,'(橫掃)RX Mapping'!AW2<=240), (-1)*('(橫掃)RX Mapping'!AW2-240),IF(AND('(橫掃)RX Mapping'!AW2>=241,'(橫掃)RX Mapping'!AW2<=360), ('(橫掃)RX Mapping'!AW2-241),IF(AND('(橫掃)RX Mapping'!AW2>=361,'(橫掃)RX Mapping'!AW2<=480), (-1)*('(橫掃)RX Mapping'!AW2-480),IF(AND('(橫掃)RX Mapping'!AW2>=481,'(橫掃)RX Mapping'!AW2<=600), ('(橫掃)RX Mapping'!AW2-361),IF(AND('(橫掃)RX Mapping'!AW2>=601,'(橫掃)RX Mapping'!AW2<=720), (-1)*('(橫掃)RX Mapping'!AW2-720)+120,IF(AND('(橫掃)RX Mapping'!AW2>=721,'(橫掃)RX Mapping'!AW2<=840), ('(橫掃)RX Mapping'!AW2-601),IF(AND('(橫掃)RX Mapping'!AW2>=841,'(橫掃)RX Mapping'!AW2<=960), (-1)*('(橫掃)RX Mapping'!AW2-960)+120,9999)))))))) -> 9999 | AX2: =IF(AND('(橫掃)RX Mapping'!AX2>=1,'(橫掃)RX Mapping'!AX2<=120), ('(橫掃)RX Mapping'!AX2-1),IF(AND('(橫掃)RX Mapping'!AX2>=121,'(橫掃)RX Mapping'!AX2<=240), (-1)*('(橫掃)RX Mapping'!AX2-240),IF(AND('(橫掃)RX Mapping'!AX2>=241,'(橫掃)RX Mapping'!AX2<=360), ('(橫掃)RX Mapping'!AX2-241),IF(AND('(橫掃)RX Mapping'!AX2>=361,'(橫掃)RX Mapping'!AX2<=480), (-1)*('(橫掃)RX Mapping'!AX2-480),IF(AND('(橫掃)RX Mapping'!AX2>=481,'(橫掃)RX Mapping'!AX2<=600), ('(橫掃)RX Mapping'!AX2-361),IF(AND('(橫掃)RX Mapping'!AX2>=601,'(橫掃)RX Mapping'!AX2<=720), (-1)*('(橫掃)RX Mapping'!AX2-720)+120,IF(AND('(橫掃)RX Mapping'!AX2>=721,'(橫掃)RX Mapping'!AX2<=840), ('(橫掃)RX Mapping'!AX2-601),IF(AND('(橫掃)RX Mapping'!AX2>=841,'(橫掃)RX Mapping'!AX2<=960), (-1)*('(橫掃)RX Mapping'!AX2-960)+120,9999)))))))) -> 9999 | AY2: =IF(AND('(橫掃)RX Mapping'!AY2>=1,'(橫掃)RX Mapping'!AY2<=120), ('(橫掃)RX Mapping'!AY2-1),IF(AND('(橫掃)RX Mapping'!AY2>=121,'(橫掃)RX Mapping'!AY2<=240), (-1)*('(橫掃)RX Mapping'!AY2-240),IF(AND('(橫掃)RX Mapping'!AY2>=241,'(橫掃)RX Mapping'!AY2<=360), ('(橫掃)RX Mapping'!AY2-241),IF(AND('(橫掃)RX Mapping'!AY2>=361,'(橫掃)RX Mapping'!AY2<=480), (-1)*('(橫掃)RX Mapping'!AY2-480),IF(AND('(橫掃)RX Mapping'!AY2>=481,'(橫掃)RX Mapping'!AY2<=600), ('(橫掃)RX Mapping'!AY2-361),IF(AND('(橫掃)RX Mapping'!AY2>=601,'(橫掃)RX Mapping'!AY2<=720), (-1)*('(橫掃)RX Mapping'!AY2-720)+120,IF(AND('(橫掃)RX Mapping'!AY2>=721,'(橫掃)RX Mapping'!AY2<=840), ('(橫掃)RX Mapping'!AY2-601),IF(AND('(橫掃)RX Mapping'!AY2>=841,'(橫掃)RX Mapping'!AY2<=960), (-1)*('(橫掃)RX Mapping'!AY2-960)+120,9999)))))))) -> 9999 | AZ2: =IF(AND('(橫掃)RX Mapping'!AZ2>=1,'(橫掃)RX Mapping'!AZ2<=120), ('(橫掃)RX Mapping'!AZ2-1),IF(AND('(橫掃)RX Mapping'!AZ2>=121,'(橫掃)RX Mapping'!AZ2<=240), (-1)*('(橫掃)RX Mapping'!AZ2-240),IF(AND('(橫掃)RX Mapping'!AZ2>=241,'(橫掃)RX Mapping'!AZ2<=360), ('(橫掃)RX Mapping'!AZ2-241),IF(AND('(橫掃)RX Mapping'!AZ2>=361,'(橫掃)RX Mapping'!AZ2<=480), (-1)*('(橫掃)RX Mapping'!AZ2-480),IF(AND('(橫掃)RX Mapping'!AZ2>=481,'(橫掃)RX Mapping'!AZ2<=600), ('(橫掃)RX Mapping'!AZ2-361),IF(AND('(橫掃)RX Mapping'!AZ2>=601,'(橫掃)RX Mapping'!AZ2<=720), (-1)*('(橫掃)RX Mapping'!AZ2-720)+120,IF(AND('(橫掃)RX Mapping'!AZ2>=721,'(橫掃)RX Mapping'!AZ2<=840), ('(橫掃)RX Mapping'!AZ2-601),IF(AND('(橫掃)RX Mapping'!AZ2>=841,'(橫掃)RX Mapping'!AZ2<=960), (-1)*('(橫掃)RX Mapping'!AZ2-960)+120,9999)))))))) -> 9999 | BA2: =IF(AND('(橫掃)RX Mapping'!BA2>=1,'(橫掃)RX Mapping'!BA2<=120), ('(橫掃)RX Mapping'!BA2-1),IF(AND('(橫掃)RX Mapping'!BA2>=121,'(橫掃)RX Mapping'!BA2<=240), (-1)*('(橫掃)RX Mapping'!BA2-240),IF(AND('(橫掃)RX Mapping'!BA2>=241,'(橫掃)RX Mapping'!BA2<=360), ('(橫掃)RX Mapping'!BA2-241),IF(AND('(橫掃)RX Mapping'!BA2>=361,'(橫掃)RX Mapping'!BA2<=480), (-1)*('(橫掃)RX Mapping'!BA2-480),IF(AND('(橫掃)RX Mapping'!BA2>=481,'(橫掃)RX Mapping'!BA2<=600), ('(橫掃)RX Mapping'!BA2-361),IF(AND('(橫掃)RX Mapping'!BA2>=601,'(橫掃)RX Mapping'!BA2<=720), (-1)*('(橫掃)RX Mapping'!BA2-720)+120,IF(AND('(橫掃)RX Mapping'!BA2>=721,'(橫掃)RX Mapping'!BA2<=840), ('(橫掃)RX Mapping'!BA2-601),IF(AND('(橫掃)RX Mapping'!BA2>=841,'(橫掃)RX Mapping'!BA2<=960), (-1)*('(橫掃)RX Mapping'!BA2-960)+120,9999)))))))) -> 9999 | ... BI2: =IF(AND('(橫掃)RX Mapping'!BI2>=1,'(橫掃)RX Mapping'!BI2<=120), ('(橫掃)RX Mapping'!BI2-1),IF(AND('(橫掃)RX Mapping'!BI2>=121,'(橫掃)RX Mapping'!BI2<=240), (-1)*('(橫掃)RX Mapping'!BI2-240),IF(AND('(橫掃)RX Mapping'!BI2>=241,'(橫掃)RX Mapping'!BI2<=360), ('(橫掃)RX Mapping'!BI2-241),IF(AND('(橫掃)RX Mapping'!BI2>=361,'(橫掃)RX Mapping'!BI2<=480), (-1)*('(橫掃)RX Mapping'!BI2-480),IF(AND('(橫掃)RX Mapping'!BI2>=481,'(橫掃)RX Mapping'!BI2<=600), ('(橫掃)RX Mapping'!BI2-361),IF(AND('(橫掃)RX Mapping'!BI2>=601,'(橫掃)RX Mapping'!BI2<=720), (-1)*('(橫掃)RX Mapping'!BI2-720)+120,IF(AND('(橫掃)RX Mapping'!BI2>=721,'(橫掃)RX Mapping'!BI2<=840), ('(橫掃)RX Mapping'!BI2-601),IF(AND('(橫掃)RX Mapping'!BI2>=841,'(橫掃)RX Mapping'!BI2<=960), (-1)*('(橫掃)RX Mapping'!BI2-960)+120,9999)))))))) -> 9999
A3: 2 | B3: =IF( (AND('(直掃)RX Mapping'!B3>=0,'(直掃)RX Mapping'!B3<=480)), (MOD('(直掃)RX Mapping'!B3,120)-1), IF( (AND('(直掃)RX Mapping'!B3>=480,'(直掃)RX Mapping'!B3<=960)), IF(MOD('(直掃)RX Mapping'!B3,120)=0, 120, 240-MOD('(直掃)RX Mapping'!B3,120)),9999))+IF(AND(MOD('(直掃)RX Mapping'!B3,120)=0, '(直掃)RX Mapping'!B3 <= 480, '(直掃)RX Mapping'!B3 > 0), 120) -> 121 | C3: =IF( (AND('(直掃)RX Mapping'!C3>=0,'(直掃)RX Mapping'!C3<=480)), (MOD('(直掃)RX Mapping'!C3,120)-1), IF( (AND('(直掃)RX Mapping'!C3>=480,'(直掃)RX Mapping'!C3<=960)), IF(MOD('(直掃)RX Mapping'!C3,120)=0, 120, 240-MOD('(直掃)RX Mapping'!C3,120)),9999))+IF(AND(MOD('(直掃)RX Mapping'!C3,120)=0, '(直掃)RX Mapping'!C3 <= 480, '(直掃)RX Mapping'!C3 > 0), 120) -> 151 | D3: =IF( (AND('(直掃)RX Mapping'!D3>=0,'(直掃)RX Mapping'!D3<=480)), (MOD('(直掃)RX Mapping'!D3,120)-1), IF( (AND('(直掃)RX Mapping'!D3>=480,'(直掃)RX Mapping'!D3<=960)), IF(MOD('(直掃)RX Mapping'!D3,120)=0, 120, 240-MOD('(直掃)RX Mapping'!D3,120)),9999))+IF(AND(MOD('(直掃)RX Mapping'!D3,120)=0, '(直掃)RX Mapping'!D3 <= 480, '(直掃)RX Mapping'!D3 > 0), 120) -> 181 | E3: =IF( (AND('(直掃)RX Mapping'!E3>=0,'(直掃)RX Mapping'!E3<=480)), (MOD('(直掃)RX Mapping'!E3,120)-1), IF( (AND('(直掃)RX Mapping'!E3>=480,'(直掃)RX Mapping'!E3<=960)), IF(MOD('(直掃)RX Mapping'!E3,120)=0, 120, 240-MOD('(直掃)RX Mapping'!E3,120)),9999))+IF(AND(MOD('(直掃)RX Mapping'!E3,120)=0, '(直掃)RX Mapping'!E3 <= 480, '(直掃)RX Mapping'!E3 > 0), 120) -> 121 | F3: =IF( (AND('(直掃)RX Mapping'!F3>=0,'(直掃)RX Mapping'!F3<=480)), (MOD('(直掃)RX Mapping'!F3,120)-1), IF( (AND('(直掃)RX Mapping'!F3>=480,'(直掃)RX Mapping'!F3<=960)), IF(MOD('(直掃)RX Mapping'!F3,120)=0, 120, 240-MOD('(直掃)RX Mapping'!F3,120)),9999))+IF(AND(MOD('(直掃)RX Mapping'!F3,120)=0, '(直掃)RX Mapping'!F3 <= 480, '(直掃)RX Mapping'!F3 > 0), 120) -> 151 | G3: =IF( (AND('(直掃)RX Mapping'!G3>=0,'(直掃)RX Mapping'!G3<=480)), (MOD('(直掃)RX Mapping'!G3,120)-1), IF( (AND('(直掃)RX Mapping'!G3>=480,'(直掃)RX Mapping'!G3<=960)), IF(MOD('(直掃)RX Mapping'!G3,120)=0, 120, 240-MOD('(直掃)RX Mapping'!G3,120)),9999))+IF(AND(MOD('(直掃)RX Mapping'!G3,120)=0, '(直掃)RX Mapping'!G3 <= 480, '(直掃)RX Mapping'!G3 > 0), 120) -> 181 | H3: =IF( (AND('(直掃)RX Mapping'!H3>=0,'(直掃)RX Mapping'!H3<=480)), (MOD('(直掃)RX Mapping'!H3,120)-1), IF( (AND('(直掃)RX Mapping'!H3>=480,'(直掃)RX Mapping'!H3<=960)), IF(MOD('(直掃)RX Mapping'!H3,120)=0, 120, 240-MOD('(直掃)RX Mapping'!H3,120)),9999))+IF(AND(MOD('(直掃)RX Mapping'!H3,120)=0, '(直掃)RX Mapping'!H3 <= 480, '(直掃)RX Mapping'!H3 > 0), 120) -> 121 | I3: =IF( (AND('(直掃)RX Mapping'!I3>=0,'(直掃)RX Mapping'!I3<=480)), (MOD('(直掃)RX Mapping'!I3,120)-1), IF( (AND('(直掃)RX Mapping'!I3>=480,'(直掃)RX Mapping'!I3<=960)), IF(MOD('(直掃)RX Mapping'!I3,120)=0, 120, 240-MOD('(直掃)RX Mapping'!I3,120)),9999))+IF(AND(MOD('(直掃)RX Mapping'!I3,120)=0, '(直掃)RX Mapping'!I3 <= 480, '(直掃)RX Mapping'!I3 > 0), 120) -> 151 | ... AS3: =IF( (AND('(直掃)RX Mapping'!AS3>=0,'(直掃)RX Mapping'!AS3<=480)), (MOD('(直掃)RX Mapping'!AS3,120)-1), IF( (AND('(直掃)RX Mapping'!AS3>=480,'(直掃)RX Mapping'!AS3<=960)), IF(MOD('(直掃)RX Mapping'!AS3,120)=0, 120, 240-MOD('(直掃)RX Mapping'!AS3,120)),9999))+IF(AND(MOD('(直掃)RX Mapping'!AS3,120)=0, '(直掃)RX Mapping'!AS3 <= 480, '(直掃)RX Mapping'!AS3 > 0), 120) -> -1 | AT3: =IF(AND('(橫掃)RX Mapping'!AT3>=1,'(橫掃)RX Mapping'!AT3<=120), ('(橫掃)RX Mapping'!AT3-1),IF(AND('(橫掃)RX Mapping'!AT3>=121,'(橫掃)RX Mapping'!AT3<=240), (-1)*('(橫掃)RX Mapping'!AT3-240),IF(AND('(橫掃)RX Mapping'!AT3>=241,'(橫掃)RX Mapping'!AT3<=360), ('(橫掃)RX Mapping'!AT3-241),IF(AND('(橫掃)RX Mapping'!AT3>=361,'(橫掃)RX Mapping'!AT3<=480), (-1)*('(橫掃)RX Mapping'!AT3-480),IF(AND('(橫掃)RX Mapping'!AT3>=481,'(橫掃)RX Mapping'!AT3<=600), ('(橫掃)RX Mapping'!AT3-361),IF(AND('(橫掃)RX Mapping'!AT3>=601,'(橫掃)RX Mapping'!AT3<=720), (-1)*('(橫掃)RX Mapping'!AT3-720)+120,IF(AND('(橫掃)RX Mapping'!AT3>=721,'(橫掃)RX Mapping'!AT3<=840), ('(橫掃)RX Mapping'!AT3-601),IF(AND('(橫掃)RX Mapping'!AT3>=841,'(橫掃)RX Mapping'!AT3<=960), (-1)*('(橫掃)RX Mapping'!AT3-960)+120,9999)))))))) -> 9999 | AU3: =IF(AND('(橫掃)RX Mapping'!AU3>=1,'(橫掃)RX Mapping'!AU3<=120), ('(橫掃)RX Mapping'!AU3-1),IF(AND('(橫掃)RX Mapping'!AU3>=121,'(橫掃)RX Mapping'!AU3<=240), (-1)*('(橫掃)RX Mapping'!AU3-240),IF(AND('(橫掃)RX Mapping'!AU3>=241,'(橫掃)RX Mapping'!AU3<=360), ('(橫掃)RX Mapping'!AU3-241),IF(AND('(橫掃)RX Mapping'!AU3>=361,'(橫掃)RX Mapping'!AU3<=480), (-1)*('(橫掃)RX Mapping'!AU3-480),IF(AND('(橫掃)RX Mapping'!AU3>=481,'(橫掃)RX Mapping'!AU3<=600), ('(橫掃)RX Mapping'!AU3-361),IF(AND('(橫掃)RX Mapping'!AU3>=601,'(橫掃)RX Mapping'!AU3<=720), (-1)*('(橫掃)RX Mapping'!AU3-720)+120,IF(AND('(橫掃)RX Mapping'!AU3>=721,'(橫掃)RX Mapping'!AU3<=840), ('(橫掃)RX Mapping'!AU3-601),IF(AND('(橫掃)RX Mapping'!AU3>=841,'(橫掃)RX Mapping'!AU3<=960), (-1)*('(橫掃)RX Mapping'!AU3-960)+120,9999)))))))) -> 9999 | AV3: =IF(AND('(橫掃)RX Mapping'!AV3>=1,'(橫掃)RX Mapping'!AV3<=120), ('(橫掃)RX Mapping'!AV3-1),IF(AND('(橫掃)RX Mapping'!AV3>=121,'(橫掃)RX Mapping'!AV3<=240), (-1)*('(橫掃)RX Mapping'!AV3-240),IF(AND('(橫掃)RX Mapping'!AV3>=241,'(橫掃)RX Mapping'!AV3<=360), ('(橫掃)RX Mapping'!AV3-241),IF(AND('(橫掃)RX Mapping'!AV3>=361,'(橫掃)RX Mapping'!AV3<=480), (-1)*('(橫掃)RX Mapping'!AV3-480),IF(AND('(橫掃)RX Mapping'!AV3>=481,'(橫掃)RX Mapping'!AV3<=600), ('(橫掃)RX Mapping'!AV3-361),IF(AND('(橫掃)RX Mapping'!AV3>=601,'(橫掃)RX Mapping'!AV3<=720), (-1)*('(橫掃)RX Mapping'!AV3-720)+120,IF(AND('(橫掃)RX Mapping'!AV3>=721,'(橫掃)RX Mapping'!AV3<=840), ('(橫掃)RX Mapping'!AV3-601),IF(AND('(橫掃)RX Mapping'!AV3>=841,'(橫掃)RX Mapping'!AV3<=960), (-1)*('(橫掃)RX Mapping'!AV3-960)+120,9999)))))))) -> 9999 | AW3: =IF(AND('(橫掃)RX Mapping'!AW3>=1,'(橫掃)RX Mapping'!AW3<=120), ('(橫掃)RX Mapping'!AW3-1),IF(AND('(橫掃)RX Mapping'!AW3>=121,'(橫掃)RX Mapping'!AW3<=240), (-1)*('(橫掃)RX Mapping'!AW3-240),IF(AND('(橫掃)RX Mapping'!AW3>=241,'(橫掃)RX Mapping'!AW3<=360), ('(橫掃)RX Mapping'!AW3-241),IF(AND('(橫掃)RX Mapping'!AW3>=361,'(橫掃)RX Mapping'!AW3<=480), (-1)*('(橫掃)RX Mapping'!AW3-480),IF(AND('(橫掃)RX Mapping'!AW3>=481,'(橫掃)RX Mapping'!AW3<=600), ('(橫掃)RX Mapping'!AW3-361),IF(AND('(橫掃)RX Mapping'!AW3>=601,'(橫掃)RX Mapping'!AW3<=720), (-1)*('(橫掃)RX Mapping'!AW3-720)+120,IF(AND('(橫掃)RX Mapping'!AW3>=721,'(橫掃)RX Mapping'!AW3<=840), ('(橫掃)RX Mapping'!AW3-601),IF(AND('(橫掃)RX Mapping'!AW3>=841,'(橫掃)RX Mapping'!AW3<=960), (-1)*('(橫掃)RX Mapping'!AW3-960)+120,9999)))))))) -> 9999 | AX3: =IF(AND('(橫掃)RX Mapping'!AX3>=1,'(橫掃)RX Mapping'!AX3<=120), ('(橫掃)RX Mapping'!AX3-1),IF(AND('(橫掃)RX Mapping'!AX3>=121,'(橫掃)RX Mapping'!AX3<=240), (-1)*('(橫掃)RX Mapping'!AX3-240),IF(AND('(橫掃)RX Mapping'!AX3>=241,'(橫掃)RX Mapping'!AX3<=360), ('(橫掃)RX Mapping'!AX3-241),IF(AND('(橫掃)RX Mapping'!AX3>=361,'(橫掃)RX Mapping'!AX3<=480), (-1)*('(橫掃)RX Mapping'!AX3-480),IF(AND('(橫掃)RX Mapping'!AX3>=481,'(橫掃)RX Mapping'!AX3<=600), ('(橫掃)RX Mapping'!AX3-361),IF(AND('(橫掃)RX Mapping'!AX3>=601,'(橫掃)RX Mapping'!AX3<=720), (-1)*('(橫掃)RX Mapping'!AX3-720)+120,IF(AND('(橫掃)RX Mapping'!AX3>=721,'(橫掃)RX Mapping'!AX3<=840), ('(橫掃)RX Mapping'!AX3-601),IF(AND('(橫掃)RX Mapping'!AX3>=841,'(橫掃)RX Mapping'!AX3<=960), (-1)*('(橫掃)RX Mapping'!AX3-960)+120,9999)))))))) -> 9999 | AY3: =IF(AND('(橫掃)RX Mapping'!AY3>=1,'(橫掃)RX Mapping'!AY3<=120), ('(橫掃)RX Mapping'!AY3-1),IF(AND('(橫掃)RX Mapping'!AY3>=121,'(橫掃)RX Mapping'!AY3<=240), (-1)*('(橫掃)RX Mapping'!AY3-240),IF(AND('(橫掃)RX Mapping'!AY3>=241,'(橫掃)RX Mapping'!AY3<=360), ('(橫掃)RX Mapping'!AY3-241),IF(AND('(橫掃)RX Mapping'!AY3>=361,'(橫掃)RX Mapping'!AY3<=480), (-1)*('(橫掃)RX Mapping'!AY3-480),IF(AND('(橫掃)RX Mapping'!AY3>=481,'(橫掃)RX Mapping'!AY3<=600), ('(橫掃)RX Mapping'!AY3-361),IF(AND('(橫掃)RX Mapping'!AY3>=601,'(橫掃)RX Mapping'!AY3<=720), (-1)*('(橫掃)RX Mapping'!AY3-720)+120,IF(AND('(橫掃)RX Mapping'!AY3>=721,'(橫掃)RX Mapping'!AY3<=840), ('(橫掃)RX Mapping'!AY3-601),IF(AND('(橫掃)RX Mapping'!AY3>=841,'(橫掃)RX Mapping'!AY3<=960), (-1)*('(橫掃)RX Mapping'!AY3-960)+120,9999)))))))) -> 9999 | AZ3: =IF(AND('(橫掃)RX Mapping'!AZ3>=1,'(橫掃)RX Mapping'!AZ3<=120), ('(橫掃)RX Mapping'!AZ3-1),IF(AND('(橫掃)RX Mapping'!AZ3>=121,'(橫掃)RX Mapping'!AZ3<=240), (-1)*('(橫掃)RX Mapping'!AZ3-240),IF(AND('(橫掃)RX Mapping'!AZ3>=241,'(橫掃)RX Mapping'!AZ3<=360), ('(橫掃)RX Mapping'!AZ3-241),IF(AND('(橫掃)RX Mapping'!AZ3>=361,'(橫掃)RX Mapping'!AZ3<=480), (-1)*('(橫掃)RX Mapping'!AZ3-480),IF(AND('(橫掃)RX Mapping'!AZ3>=481,'(橫掃)RX Mapping'!AZ3<=600), ('(橫掃)RX Mapping'!AZ3-361),IF(AND('(橫掃)RX Mapping'!AZ3>=601,'(橫掃)RX Mapping'!AZ3<=720), (-1)*('(橫掃)RX Mapping'!AZ3-720)+120,IF(AND('(橫掃)RX Mapping'!AZ3>=721,'(橫掃)RX Mapping'!AZ3<=840), ('(橫掃)RX Mapping'!AZ3-601),IF(AND('(橫掃)RX Mapping'!AZ3>=841,'(橫掃)RX Mapping'!AZ3<=960), (-1)*('(橫掃)RX Mapping'!AZ3-960)+120,9999)))))))) -> 9999 | BA3: =IF(AND('(橫掃)RX Mapping'!BA3>=1,'(橫掃)RX Mapping'!BA3<=120), ('(橫掃)RX Mapping'!BA3-1),IF(AND('(橫掃)RX Mapping'!BA3>=121,'(橫掃)RX Mapping'!BA3<=240), (-1)*('(橫掃)RX Mapping'!BA3-240),IF(AND('(橫掃)RX Mapping'!BA3>=241,'(橫掃)RX Mapping'!BA3<=360), ('(橫掃)RX Mapping'!BA3-241),IF(AND('(橫掃)RX Mapping'!BA3>=361,'(橫掃)RX Mapping'!BA3<=480), (-1)*('(橫掃)RX Mapping'!BA3-480),IF(AND('(橫掃)RX Mapping'!BA3>=481,'(橫掃)RX Mapping'!BA3<=600), ('(橫掃)RX Mapping'!BA3-361),IF(AND('(橫掃)RX Mapping'!BA3>=601,'(橫掃)RX Mapping'!BA3<=720), (-1)*('(橫掃)RX Mapping'!BA3-720)+120,IF(AND('(橫掃)RX Mapping'!BA3>=721,'(橫掃)RX Mapping'!BA3<=840), ('(橫掃)RX Mapping'!BA3-601),IF(AND('(橫掃)RX Mapping'!BA3>=841,'(橫掃)RX Mapping'!BA3<=960), (-1)*('(橫掃)RX Mapping'!BA3-960)+120,9999)))))))) -> 9999 | ... BI3: =IF(AND('(橫掃)RX Mapping'!BI3>=1,'(橫掃)RX Mapping'!BI3<=120), ('(橫掃)RX Mapping'!BI3-1),IF(AND('(橫掃)RX Mapping'!BI3>=121,'(橫掃)RX Mapping'!BI3<=240), (-1)*('(橫掃)RX Mapping'!BI3-240),IF(AND('(橫掃)RX Mapping'!BI3>=241,'(橫掃)RX Mapping'!BI3<=360), ('(橫掃)RX Mapping'!BI3-241),IF(AND('(橫掃)RX Mapping'!BI3>=361,'(橫掃)RX Mapping'!BI3<=480), (-1)*('(橫掃)RX Mapping'!BI3-480),IF(AND('(橫掃)RX Mapping'!BI3>=481,'(橫掃)RX Mapping'!BI3<=600), ('(橫掃)RX Mapping'!BI3-361),IF(AND('(橫掃)RX Mapping'!BI3>=601,'(橫掃)RX Mapping'!BI3<=720), (-1)*('(橫掃)RX Mapping'!BI3-720)+120,IF(AND('(橫掃)RX Mapping'!BI3>=721,'(橫掃)RX Mapping'!BI3<=840), ('(橫掃)RX Mapping'!BI3-601),IF(AND('(橫掃)RX Mapping'!BI3>=841,'(橫掃)RX Mapping'!BI3<=960), (-1)*('(橫掃)RX Mapping'!BI3-960)+120,9999)))))))) -> 9999
A4: 3 | B4: =IF( (AND('(直掃)RX Mapping'!B4>=0,'(直掃)RX Mapping'!B4<=480)), (MOD('(直掃)RX Mapping'!B4,120)-1), IF( (AND('(直掃)RX Mapping'!B4>=480,'(直掃)RX Mapping'!B4<=960)), IF(MOD('(直掃)RX Mapping'!B4,120)=0, 120, 240-MOD('(直掃)RX Mapping'!B4,120)),9999))+IF(AND(MOD('(直掃)RX Mapping'!B4,120)=0, '(直掃)RX Mapping'!B4 <= 480, '(直掃)RX Mapping'!B4 > 0), 120) -> 122 | C4: =IF( (AND('(直掃)RX Mapping'!C4>=0,'(直掃)RX Mapping'!C4<=480)), (MOD('(直掃)RX Mapping'!C4,120)-1), IF( (AND('(直掃)RX Mapping'!C4>=480,'(直掃)RX Mapping'!C4<=960)), IF(MOD('(直掃)RX Mapping'!C4,120)=0, 120, 240-MOD('(直掃)RX Mapping'!C4,120)),9999))+IF(AND(MOD('(直掃)RX Mapping'!C4,120)=0, '(直掃)RX Mapping'!C4 <= 480, '(直掃)RX Mapping'!C4 > 0), 120) -> 152 | D4: =IF( (AND('(直掃)RX Mapping'!D4>=0,'(直掃)RX Mapping'!D4<=480)), (MOD('(直掃)RX Mapping'!D4,120)-1), IF( (AND('(直掃)RX Mapping'!D4>=480,'(直掃)RX Mapping'!D4<=960)), IF(MOD('(直掃)RX Mapping'!D4,120)=0, 120, 240-MOD('(直掃)RX Mapping'!D4,120)),9999))+IF(AND(MOD('(直掃)RX Mapping'!D4,120)=0, '(直掃)RX Mapping'!D4 <= 480, '(直掃)RX Mapping'!D4 > 0), 120) -> 182 | E4: =IF( (AND('(直掃)RX Mapping'!E4>=0,'(直掃)RX Mapping'!E4<=480)), (MOD('(直掃)RX Mapping'!E4,120)-1), IF( (AND('(直掃)RX Mapping'!E4>=480,'(直掃)RX Mapping'!E4<=960)), IF(MOD('(直掃)RX Mapping'!E4,120)=0, 120, 240-MOD('(直掃)RX Mapping'!E4,120)),9999))+IF(AND(MOD('(直掃)RX Mapping'!E4,120)=0, '(直掃)RX Mapping'!E4 <= 480, '(直掃)RX Mapping'!E4 > 0), 120) -> 122 | F4: =IF( (AND('(直掃)RX Mapping'!F4>=0,'(直掃)RX Mapping'!F4<=480)), (MOD('(直掃)RX Mapping'!F4,120)-1), IF( (AND('(直掃)RX Mapping'!F4>=480,'(直掃)RX Mapping'!F4<=960)), IF(MOD('(直掃)RX Mapping'!F4,120)=0, 120, 240-MOD('(直掃)RX Mapping'!F4,120)),9999))+IF(AND(MOD('(直掃)RX Mapping'!F4,120)=0, '(直掃)RX Mapping'!F4 <= 480, '(直掃)RX Mapping'!F4 > 0), 120) -> 152 | G4: =IF( (AND('(直掃)RX Mapping'!G4>=0,'(直掃)RX Mapping'!G4<=480)), (MOD('(直掃)RX Mapping'!G4,120)-1), IF( (AND('(直掃)RX Mapping'!G4>=480,'(直掃)RX Mapping'!G4<=960)), IF(MOD('(直掃)RX Mapping'!G4,120)=0, 120, 240-MOD('(直掃)RX Mapping'!G4,120)),9999))+IF(AND(MOD('(直掃)RX Mapping'!G4,120)=0, '(直掃)RX Mapping'!G4 <= 480, '(直掃)RX Mapping'!G4 > 0), 120) -> 182 | H4: =IF( (AND('(直掃)RX Mapping'!H4>=0,'(直掃)RX Mapping'!H4<=480)), (MOD('(直掃)RX Mapping'!H4,120)-1), IF( (AND('(直掃)RX Mapping'!H4>=480,'(直掃)RX Mapping'!H4<=960)), IF(MOD('(直掃)RX Mapping'!H4,120)=0, 120, 240-MOD('(直掃)RX Mapping'!H4,120)),9999))+IF(AND(MOD('(直掃)RX Mapping'!H4,120)=0, '(直掃)RX Mapping'!H4 <= 480, '(直掃)RX Mapping'!H4 > 0), 120) -> 122 | I4: =IF( (AND('(直掃)RX Mapping'!I4>=0,'(直掃)RX Mapping'!I4<=480)), (MOD('(直掃)RX Mapping'!I4,120)-1), IF( (AND('(直掃)RX Mapping'!I4>=480,'(直掃)RX Mapping'!I4<=960)), IF(MOD('(直掃)RX Mapping'!I4,120)=0, 120, 240-MOD('(直掃)RX Mapping'!I4,120)),9999))+IF(AND(MOD('(直掃)RX Mapping'!I4,120)=0, '(直掃)RX Mapping'!I4 <= 480, '(直掃)RX Mapping'!I4 > 0), 120) -> 152 | ... AS4: =IF( (AND('(直掃)RX Mapping'!AS4>=0,'(直掃)RX Mapping'!AS4<=480)), (MOD('(直掃)RX Mapping'!AS4,120)-1), IF( (AND('(直掃)RX Mapping'!AS4>=480,'(直掃)RX Mapping'!AS4<=960)), IF(MOD('(直掃)RX Mapping'!AS4,120)=0, 120, 240-MOD('(直掃)RX Mapping'!AS4,120)),9999))+IF(AND(MOD('(直掃)RX Mapping'!AS4,120)=0, '(直掃)RX Mapping'!AS4 <= 480, '(直掃)RX Mapping'!AS4 > 0), 120) -> -1 | AT4: =IF(AND('(橫掃)RX Mapping'!AT4>=1,'(橫掃)RX Mapping'!AT4<=120), ('(橫掃)RX Mapping'!AT4-1),IF(AND('(橫掃)RX Mapping'!AT4>=121,'(橫掃)RX Mapping'!AT4<=240), (-1)*('(橫掃)RX Mapping'!AT4-240),IF(AND('(橫掃)RX Mapping'!AT4>=241,'(橫掃)RX Mapping'!AT4<=360), ('(橫掃)RX Mapping'!AT4-241),IF(AND('(橫掃)RX Mapping'!AT4>=361,'(橫掃)RX Mapping'!AT4<=480), (-1)*('(橫掃)RX Mapping'!AT4-480),IF(AND('(橫掃)RX Mapping'!AT4>=481,'(橫掃)RX Mapping'!AT4<=600), ('(橫掃)RX Mapping'!AT4-361),IF(AND('(橫掃)RX Mapping'!AT4>=601,'(橫掃)RX Mapping'!AT4<=720), (-1)*('(橫掃)RX Mapping'!AT4-720)+120,IF(AND('(橫掃)RX Mapping'!AT4>=721,'(橫掃)RX Mapping'!AT4<=840), ('(橫掃)RX Mapping'!AT4-601),IF(AND('(橫掃)RX Mapping'!AT4>=841,'(橫掃)RX Mapping'!AT4<=960), (-1)*('(橫掃)RX Mapping'!AT4-960)+120,9999)))))))) -> 9999 | AU4: =IF(AND('(橫掃)RX Mapping'!AU4>=1,'(橫掃)RX Mapping'!AU4<=120), ('(橫掃)RX Mapping'!AU4-1),IF(AND('(橫掃)RX Mapping'!AU4>=121,'(橫掃)RX Mapping'!AU4<=240), (-1)*('(橫掃)RX Mapping'!AU4-240),IF(AND('(橫掃)RX Mapping'!AU4>=241,'(橫掃)RX Mapping'!AU4<=360), ('(橫掃)RX Mapping'!AU4-241),IF(AND('(橫掃)RX Mapping'!AU4>=361,'(橫掃)RX Mapping'!AU4<=480), (-1)*('(橫掃)RX Mapping'!AU4-480),IF(AND('(橫掃)RX Mapping'!AU4>=481,'(橫掃)RX Mapping'!AU4<=600), ('(橫掃)RX Mapping'!AU4-361),IF(AND('(橫掃)RX Mapping'!AU4>=601,'(橫掃)RX Mapping'!AU4<=720), (-1)*('(橫掃)RX Mapping'!AU4-720)+120,IF(AND('(橫掃)RX Mapping'!AU4>=721,'(橫掃)RX Mapping'!AU4<=840), ('(橫掃)RX Mapping'!AU4-601),IF(AND('(橫掃)RX Mapping'!AU4>=841,'(橫掃)RX Mapping'!AU4<=960), (-1)*('(橫掃)RX Mapping'!AU4-960)+120,9999)))))))) -> 9999 | AV4: =IF(AND('(橫掃)RX Mapping'!AV4>=1,'(橫掃)RX Mapping'!AV4<=120), ('(橫掃)RX Mapping'!AV4-1),IF(AND('(橫掃)RX Mapping'!AV4>=121,'(橫掃)RX Mapping'!AV4<=240), (-1)*('(橫掃)RX Mapping'!AV4-240),IF(AND('(橫掃)RX Mapping'!AV4>=241,'(橫掃)RX Mapping'!AV4<=360), ('(橫掃)RX Mapping'!AV4-241),IF(AND('(橫掃)RX Mapping'!AV4>=361,'(橫掃)RX Mapping'!AV4<=480), (-1)*('(橫掃)RX Mapping'!AV4-480),IF(AND('(橫掃)RX Mapping'!AV4>=481,'(橫掃)RX Mapping'!AV4<=600), ('(橫掃)RX Mapping'!AV4-361),IF(AND('(橫掃)RX Mapping'!AV4>=601,'(橫掃)RX Mapping'!AV4<=720), (-1)*('(橫掃)RX Mapping'!AV4-720)+120,IF(AND('(橫掃)RX Mapping'!AV4>=721,'(橫掃)RX Mapping'!AV4<=840), ('(橫掃)RX Mapping'!AV4-601),IF(AND('(橫掃)RX Mapping'!AV4>=841,'(橫掃)RX Mapping'!AV4<=960), (-1)*('(橫掃)RX Mapping'!AV4-960)+120,9999)))))))) -> 9999 | AW4: =IF(AND('(橫掃)RX Mapping'!AW4>=1,'(橫掃)RX Mapping'!AW4<=120), ('(橫掃)RX Mapping'!AW4-1),IF(AND('(橫掃)RX Mapping'!AW4>=121,'(橫掃)RX Mapping'!AW4<=240), (-1)*('(橫掃)RX Mapping'!AW4-240),IF(AND('(橫掃)RX Mapping'!AW4>=241,'(橫掃)RX Mapping'!AW4<=360), ('(橫掃)RX Mapping'!AW4-241),IF(AND('(橫掃)RX Mapping'!AW4>=361,'(橫掃)RX Mapping'!AW4<=480), (-1)*('(橫掃)RX Mapping'!AW4-480),IF(AND('(橫掃)RX Mapping'!AW4>=481,'(橫掃)RX Mapping'!AW4<=600), ('(橫掃)RX Mapping'!AW4-361),IF(AND('(橫掃)RX Mapping'!AW4>=601,'(橫掃)RX Mapping'!AW4<=720), (-1)*('(橫掃)RX Mapping'!AW4-720)+120,IF(AND('(橫掃)RX Mapping'!AW4>=721,'(橫掃)RX Mapping'!AW4<=840), ('(橫掃)RX Mapping'!AW4-601),IF(AND('(橫掃)RX Mapping'!AW4>=841,'(橫掃)RX Mapping'!AW4<=960), (-1)*('(橫掃)RX Mapping'!AW4-960)+120,9999)))))))) -> 9999 | AX4: =IF(AND('(橫掃)RX Mapping'!AX4>=1,'(橫掃)RX Mapping'!AX4<=120), ('(橫掃)RX Mapping'!AX4-1),IF(AND('(橫掃)RX Mapping'!AX4>=121,'(橫掃)RX Mapping'!AX4<=240), (-1)*('(橫掃)RX Mapping'!AX4-240),IF(AND('(橫掃)RX Mapping'!AX4>=241,'(橫掃)RX Mapping'!AX4<=360), ('(橫掃)RX Mapping'!AX4-241),IF(AND('(橫掃)RX Mapping'!AX4>=361,'(橫掃)RX Mapping'!AX4<=480), (-1)*('(橫掃)RX Mapping'!AX4-480),IF(AND('(橫掃)RX Mapping'!AX4>=481,'(橫掃)RX Mapping'!AX4<=600), ('(橫掃)RX Mapping'!AX4-361),IF(AND('(橫掃)RX Mapping'!AX4>=601,'(橫掃)RX Mapping'!AX4<=720), (-1)*('(橫掃)RX Mapping'!AX4-720)+120,IF(AND('(橫掃)RX Mapping'!AX4>=721,'(橫掃)RX Mapping'!AX4<=840), ('(橫掃)RX Mapping'!AX4-601),IF(AND('(橫掃)RX Mapping'!AX4>=841,'(橫掃)RX Mapping'!AX4<=960), (-1)*('(橫掃)RX Mapping'!AX4-960)+120,9999)))))))) -> 9999 | AY4: =IF(AND('(橫掃)RX Mapping'!AY4>=1,'(橫掃)RX Mapping'!AY4<=120), ('(橫掃)RX Mapping'!AY4-1),IF(AND('(橫掃)RX Mapping'!AY4>=121,'(橫掃)RX Mapping'!AY4<=240), (-1)*('(橫掃)RX Mapping'!AY4-240),IF(AND('(橫掃)RX Mapping'!AY4>=241,'(橫掃)RX Mapping'!AY4<=360), ('(橫掃)RX Mapping'!AY4-241),IF(AND('(橫掃)RX Mapping'!AY4>=361,'(橫掃)RX Mapping'!AY4<=480), (-1)*('(橫掃)RX Mapping'!AY4-480),IF(AND('(橫掃)RX Mapping'!AY4>=481,'(橫掃)RX Mapping'!AY4<=600), ('(橫掃)RX Mapping'!AY4-361),IF(AND('(橫掃)RX Mapping'!AY4>=601,'(橫掃)RX Mapping'!AY4<=720), (-1)*('(橫掃)RX Mapping'!AY4-720)+120,IF(AND('(橫掃)RX Mapping'!AY4>=721,'(橫掃)RX Mapping'!AY4<=840), ('(橫掃)RX Mapping'!AY4-601),IF(AND('(橫掃)RX Mapping'!AY4>=841,'(橫掃)RX Mapping'!AY4<=960), (-1)*('(橫掃)RX Mapping'!AY4-960)+120,9999)))))))) -> 9999 | AZ4: =IF(AND('(橫掃)RX Mapping'!AZ4>=1,'(橫掃)RX Mapping'!AZ4<=120), ('(橫掃)RX Mapping'!AZ4-1),IF(AND('(橫掃)RX Mapping'!AZ4>=121,'(橫掃)RX Mapping'!AZ4<=240), (-1)*('(橫掃)RX Mapping'!AZ4-240),IF(AND('(橫掃)RX Mapping'!AZ4>=241,'(橫掃)RX Mapping'!AZ4<=360), ('(橫掃)RX Mapping'!AZ4-241),IF(AND('(橫掃)RX Mapping'!AZ4>=361,'(橫掃)RX Mapping'!AZ4<=480), (-1)*('(橫掃)RX Mapping'!AZ4-480),IF(AND('(橫掃)RX Mapping'!AZ4>=481,'(橫掃)RX Mapping'!AZ4<=600), ('(橫掃)RX Mapping'!AZ4-361),IF(AND('(橫掃)RX Mapping'!AZ4>=601,'(橫掃)RX Mapping'!AZ4<=720), (-1)*('(橫掃)RX Mapping'!AZ4-720)+120,IF(AND('(橫掃)RX Mapping'!AZ4>=721,'(橫掃)RX Mapping'!AZ4<=840), ('(橫掃)RX Mapping'!AZ4-601),IF(AND('(橫掃)RX Mapping'!AZ4>=841,'(橫掃)RX Mapping'!AZ4<=960), (-1)*('(橫掃)RX Mapping'!AZ4-960)+120,9999)))))))) -> 9999 | BA4: =IF(AND('(橫掃)RX Mapping'!BA4>=1,'(橫掃)RX Mapping'!BA4<=120), ('(橫掃)RX Mapping'!BA4-1),IF(AND('(橫掃)RX Mapping'!BA4>=121,'(橫掃)RX Mapping'!BA4<=240), (-1)*('(橫掃)RX Mapping'!BA4-240),IF(AND('(橫掃)RX Mapping'!BA4>=241,'(橫掃)RX Mapping'!BA4<=360), ('(橫掃)RX Mapping'!BA4-241),IF(AND('(橫掃)RX Mapping'!BA4>=361,'(橫掃)RX Mapping'!BA4<=480), (-1)*('(橫掃)RX Mapping'!BA4-480),IF(AND('(橫掃)RX Mapping'!BA4>=481,'(橫掃)RX Mapping'!BA4<=600), ('(橫掃)RX Mapping'!BA4-361),IF(AND('(橫掃)RX Mapping'!BA4>=601,'(橫掃)RX Mapping'!BA4<=720), (-1)*('(橫掃)RX Mapping'!BA4-720)+120,IF(AND('(橫掃)RX Mapping'!BA4>=721,'(橫掃)RX Mapping'!BA4<=840), ('(橫掃)RX Mapping'!BA4-601),IF(AND('(橫掃)RX Mapping'!BA4>=841,'(橫掃)RX Mapping'!BA4<=960), (-1)*('(橫掃)RX Mapping'!BA4-960)+120,9999)))))))) -> 9999 | ... BI4: =IF(AND('(橫掃)RX Mapping'!BI4>=1,'(橫掃)RX Mapping'!BI4<=120), ('(橫掃)RX Mapping'!BI4-1),IF(AND('(橫掃)RX Mapping'!BI4>=121,'(橫掃)RX Mapping'!BI4<=240), (-1)*('(橫掃)RX Mapping'!BI4-240),IF(AND('(橫掃)RX Mapping'!BI4>=241,'(橫掃)RX Mapping'!BI4<=360), ('(橫掃)RX Mapping'!BI4-241),IF(AND('(橫掃)RX Mapping'!BI4>=361,'(橫掃)RX Mapping'!BI4<=480), (-1)*('(橫掃)RX Mapping'!BI4-480),IF(AND('(橫掃)RX Mapping'!BI4>=481,'(橫掃)RX Mapping'!BI4<=600), ('(橫掃)RX Mapping'!BI4-361),IF(AND('(橫掃)RX Mapping'!BI4>=601,'(橫掃)RX Mapping'!BI4<=720), (-1)*('(橫掃)RX Mapping'!BI4-720)+120,IF(AND('(橫掃)RX Mapping'!BI4>=721,'(橫掃)RX Mapping'!BI4<=840), ('(橫掃)RX Mapping'!BI4-601),IF(AND('(橫掃)RX Mapping'!BI4>=841,'(橫掃)RX Mapping'!BI4<=960), (-1)*('(橫掃)RX Mapping'!BI4-960)+120,9999)))))))) -> 9999
A5: 4 | B5: =IF( (AND('(直掃)RX Mapping'!B5>=0,'(直掃)RX Mapping'!B5<=480)), (MOD('(直掃)RX Mapping'!B5,120)-1), IF( (AND('(直掃)RX Mapping'!B5>=480,'(直掃)RX Mapping'!B5<=960)), IF(MOD('(直掃)RX Mapping'!B5,120)=0, 120, 240-MOD('(直掃)RX Mapping'!B5,120)),9999))+IF(AND(MOD('(直掃)RX Mapping'!B5,120)=0, '(直掃)RX Mapping'!B5 <= 480, '(直掃)RX Mapping'!B5 > 0), 120) -> 123 | C5: =IF( (AND('(直掃)RX Mapping'!C5>=0,'(直掃)RX Mapping'!C5<=480)), (MOD('(直掃)RX Mapping'!C5,120)-1), IF( (AND('(直掃)RX Mapping'!C5>=480,'(直掃)RX Mapping'!C5<=960)), IF(MOD('(直掃)RX Mapping'!C5,120)=0, 120, 240-MOD('(直掃)RX Mapping'!C5,120)),9999))+IF(AND(MOD('(直掃)RX Mapping'!C5,120)=0, '(直掃)RX Mapping'!C5 <= 480, '(直掃)RX Mapping'!C5 > 0), 120) -> 153 | D5: =IF( (AND('(直掃)RX Mapping'!D5>=0,'(直掃)RX Mapping'!D5<=480)), (MOD('(直掃)RX Mapping'!D5,120)-1), IF( (AND('(直掃)RX Mapping'!D5>=480,'(直掃)RX Mapping'!D5<=960)), IF(MOD('(直掃)RX Mapping'!D5,120)=0, 120, 240-MOD('(直掃)RX Mapping'!D5,120)),9999))+IF(AND(MOD('(直掃)RX Mapping'!D5,120)=0, '(直掃)RX Mapping'!D5 <= 480, '(直掃)RX Mapping'!D5 > 0), 120) -> 183 | E5: =IF( (AND('(直掃)RX Mapping'!E5>=0,'(直掃)RX Mapping'!E5<=480)), (MOD('(直掃)RX Mapping'!E5,120)-1), IF( (AND('(直掃)RX Mapping'!E5>=480,'(直掃)RX Mapping'!E5<=960)), IF(MOD('(直掃)RX Mapping'!E5,120)=0, 120, 240-MOD('(直掃)RX Mapping'!E5,120)),9999))+IF(AND(MOD('(直掃)RX Mapping'!E5,120)=0, '(直掃)RX Mapping'!E5 <= 480, '(直掃)RX Mapping'!E5 > 0), 120) -> 123 | F5: =IF( (AND('(直掃)RX Mapping'!F5>=0,'(直掃)RX Mapping'!F5<=480)), (MOD('(直掃)RX Mapping'!F5,120)-1), IF( (AND('(直掃)RX Mapping'!F5>=480,'(直掃)RX Mapping'!F5<=960)), IF(MOD('(直掃)RX Mapping'!F5,120)=0, 120, 240-MOD('(直掃)RX Mapping'!F5,120)),9999))+IF(AND(MOD('(直掃)RX Mapping'!F5,120)=0, '(直掃)RX Mapping'!F5 <= 480, '(直掃)RX Mapping'!F5 > 0), 120) -> 153 | G5: =IF( (AND('(直掃)RX Mapping'!G5>=0,'(直掃)RX Mapping'!G5<=480)), (MOD('(直掃)RX Mapping'!G5,120)-1), IF( (AND('(直掃)RX Mapping'!G5>=480,'(直掃)RX Mapping'!G5<=960)), IF(MOD('(直掃)RX Mapping'!G5,120)=0, 120, 240-MOD('(直掃)RX Mapping'!G5,120)),9999))+IF(AND(MOD('(直掃)RX Mapping'!G5,120)=0, '(直掃)RX Mapping'!G5 <= 480, '(直掃)RX Mapping'!G5 > 0), 120) -> 183 | H5: =IF( (AND('(直掃)RX Mapping'!H5>=0,'(直掃)RX Mapping'!H5<=480)), (MOD('(直掃)RX Mapping'!H5,120)-1), IF( (AND('(直掃)RX Mapping'!H5>=480,'(直掃)RX Mapping'!H5<=960)), IF(MOD('(直掃)RX Mapping'!H5,120)=0, 120, 240-MOD('(直掃)RX Mapping'!H5,120)),9999))+IF(AND(MOD('(直掃)RX Mapping'!H5,120)=0, '(直掃)RX Mapping'!H5 <= 480, '(直掃)RX Mapping'!H5 > 0), 120) -> 123 | I5: =IF( (AND('(直掃)RX Mapping'!I5>=0,'(直掃)RX Mapping'!I5<=480)), (MOD('(直掃)RX Mapping'!I5,120)-1), IF( (AND('(直掃)RX Mapping'!I5>=480,'(直掃)RX Mapping'!I5<=960)), IF(MOD('(直掃)RX Mapping'!I5,120)=0, 120, 240-MOD('(直掃)RX Mapping'!I5,120)),9999))+IF(AND(MOD('(直掃)RX Mapping'!I5,120)=0, '(直掃)RX Mapping'!I5 <= 480, '(直掃)RX Mapping'!I5 > 0), 120) -> 153 | ... AS5: =IF( (AND('(直掃)RX Mapping'!AS5>=0,'(直掃)RX Mapping'!AS5<=480)), (MOD('(直掃)RX Mapping'!AS5,120)-1), IF( (AND('(直掃)RX Mapping'!AS5>=480,'(直掃)RX Mapping'!AS5<=960)), IF(MOD('(直掃)RX Mapping'!AS5,120)=0, 120, 240-MOD('(直掃)RX Mapping'!AS5,120)),9999))+IF(AND(MOD('(直掃)RX Mapping'!AS5,120)=0, '(直掃)RX Mapping'!AS5 <= 480, '(直掃)RX Mapping'!AS5 > 0), 120) -> -1 | AT5: =IF(AND('(橫掃)RX Mapping'!AT5>=1,'(橫掃)RX Mapping'!AT5<=120), ('(橫掃)RX Mapping'!AT5-1),IF(AND('(橫掃)RX Mapping'!AT5>=121,'(橫掃)RX Mapping'!AT5<=240), (-1)*('(橫掃)RX Mapping'!AT5-240),IF(AND('(橫掃)RX Mapping'!AT5>=241,'(橫掃)RX Mapping'!AT5<=360), ('(橫掃)RX Mapping'!AT5-241),IF(AND('(橫掃)RX Mapping'!AT5>=361,'(橫掃)RX Mapping'!AT5<=480), (-1)*('(橫掃)RX Mapping'!AT5-480),IF(AND('(橫掃)RX Mapping'!AT5>=481,'(橫掃)RX Mapping'!AT5<=600), ('(橫掃)RX Mapping'!AT5-361),IF(AND('(橫掃)RX Mapping'!AT5>=601,'(橫掃)RX Mapping'!AT5<=720), (-1)*('(橫掃)RX Mapping'!AT5-720)+120,IF(AND('(橫掃)RX Mapping'!AT5>=721,'(橫掃)RX Mapping'!AT5<=840), ('(橫掃)RX Mapping'!AT5-601),IF(AND('(橫掃)RX Mapping'!AT5>=841,'(橫掃)RX Mapping'!AT5<=960), (-1)*('(橫掃)RX Mapping'!AT5-960)+120,9999)))))))) -> 9999 | AU5: =IF(AND('(橫掃)RX Mapping'!AU5>=1,'(橫掃)RX Mapping'!AU5<=120), ('(橫掃)RX Mapping'!AU5-1),IF(AND('(橫掃)RX Mapping'!AU5>=121,'(橫掃)RX Mapping'!AU5<=240), (-1)*('(橫掃)RX Mapping'!AU5-240),IF(AND('(橫掃)RX Mapping'!AU5>=241,'(橫掃)RX Mapping'!AU5<=360), ('(橫掃)RX Mapping'!AU5-241),IF(AND('(橫掃)RX Mapping'!AU5>=361,'(橫掃)RX Mapping'!AU5<=480), (-1)*('(橫掃)RX Mapping'!AU5-480),IF(AND('(橫掃)RX Mapping'!AU5>=481,'(橫掃)RX Mapping'!AU5<=600), ('(橫掃)RX Mapping'!AU5-361),IF(AND('(橫掃)RX Mapping'!AU5>=601,'(橫掃)RX Mapping'!AU5<=720), (-1)*('(橫掃)RX Mapping'!AU5-720)+120,IF(AND('(橫掃)RX Mapping'!AU5>=721,'(橫掃)RX Mapping'!AU5<=840), ('(橫掃)RX Mapping'!AU5-601),IF(AND('(橫掃)RX Mapping'!AU5>=841,'(橫掃)RX Mapping'!AU5<=960), (-1)*('(橫掃)RX Mapping'!AU5-960)+120,9999)))))))) -> 9999 | AV5: =IF(AND('(橫掃)RX Mapping'!AV5>=1,'(橫掃)RX Mapping'!AV5<=120), ('(橫掃)RX Mapping'!AV5-1),IF(AND('(橫掃)RX Mapping'!AV5>=121,'(橫掃)RX Mapping'!AV5<=240), (-1)*('(橫掃)RX Mapping'!AV5-240),IF(AND('(橫掃)RX Mapping'!AV5>=241,'(橫掃)RX Mapping'!AV5<=360), ('(橫掃)RX Mapping'!AV5-241),IF(AND('(橫掃)RX Mapping'!AV5>=361,'(橫掃)RX Mapping'!AV5<=480), (-1)*('(橫掃)RX Mapping'!AV5-480),IF(AND('(橫掃)RX Mapping'!AV5>=481,'(橫掃)RX Mapping'!AV5<=600), ('(橫掃)RX Mapping'!AV5-361),IF(AND('(橫掃)RX Mapping'!AV5>=601,'(橫掃)RX Mapping'!AV5<=720), (-1)*('(橫掃)RX Mapping'!AV5-720)+120,IF(AND('(橫掃)RX Mapping'!AV5>=721,'(橫掃)RX Mapping'!AV5<=840), ('(橫掃)RX Mapping'!AV5-601),IF(AND('(橫掃)RX Mapping'!AV5>=841,'(橫掃)RX Mapping'!AV5<=960), (-1)*('(橫掃)RX Mapping'!AV5-960)+120,9999)))))))) -> 9999 | AW5: =IF(AND('(橫掃)RX Mapping'!AW5>=1,'(橫掃)RX Mapping'!AW5<=120), ('(橫掃)RX Mapping'!AW5-1),IF(AND('(橫掃)RX Mapping'!AW5>=121,'(橫掃)RX Mapping'!AW5<=240), (-1)*('(橫掃)RX Mapping'!AW5-240),IF(AND('(橫掃)RX Mapping'!AW5>=241,'(橫掃)RX Mapping'!AW5<=360), ('(橫掃)RX Mapping'!AW5-241),IF(AND('(橫掃)RX Mapping'!AW5>=361,'(橫掃)RX Mapping'!AW5<=480), (-1)*('(橫掃)RX Mapping'!AW5-480),IF(AND('(橫掃)RX Mapping'!AW5>=481,'(橫掃)RX Mapping'!AW5<=600), ('(橫掃)RX Mapping'!AW5-361),IF(AND('(橫掃)RX Mapping'!AW5>=601,'(橫掃)RX Mapping'!AW5<=720), (-1)*('(橫掃)RX Mapping'!AW5-720)+120,IF(AND('(橫掃)RX Mapping'!AW5>=721,'(橫掃)RX Mapping'!AW5<=840), ('(橫掃)RX Mapping'!AW5-601),IF(AND('(橫掃)RX Mapping'!AW5>=841,'(橫掃)RX Mapping'!AW5<=960), (-1)*('(橫掃)RX Mapping'!AW5-960)+120,9999)))))))) -> 9999 | AX5: =IF(AND('(橫掃)RX Mapping'!AX5>=1,'(橫掃)RX Mapping'!AX5<=120), ('(橫掃)RX Mapping'!AX5-1),IF(AND('(橫掃)RX Mapping'!AX5>=121,'(橫掃)RX Mapping'!AX5<=240), (-1)*('(橫掃)RX Mapping'!AX5-240),IF(AND('(橫掃)RX Mapping'!AX5>=241,'(橫掃)RX Mapping'!AX5<=360), ('(橫掃)RX Mapping'!AX5-241),IF(AND('(橫掃)RX Mapping'!AX5>=361,'(橫掃)RX Mapping'!AX5<=480), (-1)*('(橫掃)RX Mapping'!AX5-480),IF(AND('(橫掃)RX Mapping'!AX5>=481,'(橫掃)RX Mapping'!AX5<=600), ('(橫掃)RX Mapping'!AX5-361),IF(AND('(橫掃)RX Mapping'!AX5>=601,'(橫掃)RX Mapping'!AX5<=720), (-1)*('(橫掃)RX Mapping'!AX5-720)+120,IF(AND('(橫掃)RX Mapping'!AX5>=721,'(橫掃)RX Mapping'!AX5<=840), ('(橫掃)RX Mapping'!AX5-601),IF(AND('(橫掃)RX Mapping'!AX5>=841,'(橫掃)RX Mapping'!AX5<=960), (-1)*('(橫掃)RX Mapping'!AX5-960)+120,9999)))))))) -> 9999 | AY5: =IF(AND('(橫掃)RX Mapping'!AY5>=1,'(橫掃)RX Mapping'!AY5<=120), ('(橫掃)RX Mapping'!AY5-1),IF(AND('(橫掃)RX Mapping'!AY5>=121,'(橫掃)RX Mapping'!AY5<=240), (-1)*('(橫掃)RX Mapping'!AY5-240),IF(AND('(橫掃)RX Mapping'!AY5>=241,'(橫掃)RX Mapping'!AY5<=360), ('(橫掃)RX Mapping'!AY5-241),IF(AND('(橫掃)RX Mapping'!AY5>=361,'(橫掃)RX Mapping'!AY5<=480), (-1)*('(橫掃)RX Mapping'!AY5-480),IF(AND('(橫掃)RX Mapping'!AY5>=481,'(橫掃)RX Mapping'!AY5<=600), ('(橫掃)RX Mapping'!AY5-361),IF(AND('(橫掃)RX Mapping'!AY5>=601,'(橫掃)RX Mapping'!AY5<=720), (-1)*('(橫掃)RX Mapping'!AY5-720)+120,IF(AND('(橫掃)RX Mapping'!AY5>=721,'(橫掃)RX Mapping'!AY5<=840), ('(橫掃)RX Mapping'!AY5-601),IF(AND('(橫掃)RX Mapping'!AY5>=841,'(橫掃)RX Mapping'!AY5<=960), (-1)*('(橫掃)RX Mapping'!AY5-960)+120,9999)))))))) -> 9999 | AZ5: =IF(AND('(橫掃)RX Mapping'!AZ5>=1,'(橫掃)RX Mapping'!AZ5<=120), ('(橫掃)RX Mapping'!AZ5-1),IF(AND('(橫掃)RX Mapping'!AZ5>=121,'(橫掃)RX Mapping'!AZ5<=240), (-1)*('(橫掃)RX Mapping'!AZ5-240),IF(AND('(橫掃)RX Mapping'!AZ5>=241,'(橫掃)RX Mapping'!AZ5<=360), ('(橫掃)RX Mapping'!AZ5-241),IF(AND('(橫掃)RX Mapping'!AZ5>=361,'(橫掃)RX Mapping'!AZ5<=480), (-1)*('(橫掃)RX Mapping'!AZ5-480),IF(AND('(橫掃)RX Mapping'!AZ5>=481,'(橫掃)RX Mapping'!AZ5<=600), ('(橫掃)RX Mapping'!AZ5-361),IF(AND('(橫掃)RX Mapping'!AZ5>=601,'(橫掃)RX Mapping'!AZ5<=720), (-1)*('(橫掃)RX Mapping'!AZ5-720)+120,IF(AND('(橫掃)RX Mapping'!AZ5>=721,'(橫掃)RX Mapping'!AZ5<=840), ('(橫掃)RX Mapping'!AZ5-601),IF(AND('(橫掃)RX Mapping'!AZ5>=841,'(橫掃)RX Mapping'!AZ5<=960), (-1)*('(橫掃)RX Mapping'!AZ5-960)+120,9999)))))))) -> 9999 | BA5: =IF(AND('(橫掃)RX Mapping'!BA5>=1,'(橫掃)RX Mapping'!BA5<=120), ('(橫掃)RX Mapping'!BA5-1),IF(AND('(橫掃)RX Mapping'!BA5>=121,'(橫掃)RX Mapping'!BA5<=240), (-1)*('(橫掃)RX Mapping'!BA5-240),IF(AND('(橫掃)RX Mapping'!BA5>=241,'(橫掃)RX Mapping'!BA5<=360), ('(橫掃)RX Mapping'!BA5-241),IF(AND('(橫掃)RX Mapping'!BA5>=361,'(橫掃)RX Mapping'!BA5<=480), (-1)*('(橫掃)RX Mapping'!BA5-480),IF(AND('(橫掃)RX Mapping'!BA5>=481,'(橫掃)RX Mapping'!BA5<=600), ('(橫掃)RX Mapping'!BA5-361),IF(AND('(橫掃)RX Mapping'!BA5>=601,'(橫掃)RX Mapping'!BA5<=720), (-1)*('(橫掃)RX Mapping'!BA5-720)+120,IF(AND('(橫掃)RX Mapping'!BA5>=721,'(橫掃)RX Mapping'!BA5<=840), ('(橫掃)RX Mapping'!BA5-601),IF(AND('(橫掃)RX Mapping'!BA5>=841,'(橫掃)RX Mapping'!BA5<=960), (-1)*('(橫掃)RX Mapping'!BA5-960)+120,9999)))))))) -> 9999 | ... BI5: =IF(AND('(橫掃)RX Mapping'!BI5>=1,'(橫掃)RX Mapping'!BI5<=120), ('(橫掃)RX Mapping'!BI5-1),IF(AND('(橫掃)RX Mapping'!BI5>=121,'(橫掃)RX Mapping'!BI5<=240), (-1)*('(橫掃)RX Mapping'!BI5-240),IF(AND('(橫掃)RX Mapping'!BI5>=241,'(橫掃)RX Mapping'!BI5<=360), ('(橫掃)RX Mapping'!BI5-241),IF(AND('(橫掃)RX Mapping'!BI5>=361,'(橫掃)RX Mapping'!BI5<=480), (-1)*('(橫掃)RX Mapping'!BI5-480),IF(AND('(橫掃)RX Mapping'!BI5>=481,'(橫掃)RX Mapping'!BI5<=600), ('(橫掃)RX Mapping'!BI5-361),IF(AND('(橫掃)RX Mapping'!BI5>=601,'(橫掃)RX Mapping'!BI5<=720), (-1)*('(橫掃)RX Mapping'!BI5-720)+120,IF(AND('(橫掃)RX Mapping'!BI5>=721,'(橫掃)RX Mapping'!BI5<=840), ('(橫掃)RX Mapping'!BI5-601),IF(AND('(橫掃)RX Mapping'!BI5>=841,'(橫掃)RX Mapping'!BI5<=960), (-1)*('(橫掃)RX Mapping'!BI5-960)+120,9999)))))))) -> 9999
A6: 5 | B6: =IF( (AND('(直掃)RX Mapping'!B6>=0,'(直掃)RX Mapping'!B6<=480)), (MOD('(直掃)RX Mapping'!B6,120)-1), IF( (AND('(直掃)RX Mapping'!B6>=480,'(直掃)RX Mapping'!B6<=960)), IF(MOD('(直掃)RX Mapping'!B6,120)=0, 120, 240-MOD('(直掃)RX Mapping'!B6,120)),9999))+IF(AND(MOD('(直掃)RX Mapping'!B6,120)=0, '(直掃)RX Mapping'!B6 <= 480, '(直掃)RX Mapping'!B6 > 0), 120) -> 124 | C6: =IF( (AND('(直掃)RX Mapping'!C6>=0,'(直掃)RX Mapping'!C6<=480)), (MOD('(直掃)RX Mapping'!C6,120)-1), IF( (AND('(直掃)RX Mapping'!C6>=480,'(直掃)RX Mapping'!C6<=960)), IF(MOD('(直掃)RX Mapping'!C6,120)=0, 120, 240-MOD('(直掃)RX Mapping'!C6,120)),9999))+IF(AND(MOD('(直掃)RX Mapping'!C6,120)=0, '(直掃)RX Mapping'!C6 <= 480, '(直掃)RX Mapping'!C6 > 0), 120) -> 154 | D6: =IF( (AND('(直掃)RX Mapping'!D6>=0,'(直掃)RX Mapping'!D6<=480)), (MOD('(直掃)RX Mapping'!D6,120)-1), IF( (AND('(直掃)RX Mapping'!D6>=480,'(直掃)RX Mapping'!D6<=960)), IF(MOD('(直掃)RX Mapping'!D6,120)=0, 120, 240-MOD('(直掃)RX Mapping'!D6,120)),9999))+IF(AND(MOD('(直掃)RX Mapping'!D6,120)=0, '(直掃)RX Mapping'!D6 <= 480, '(直掃)RX Mapping'!D6 > 0), 120) -> 184 | E6: =IF( (AND('(直掃)RX Mapping'!E6>=0,'(直掃)RX Mapping'!E6<=480)), (MOD('(直掃)RX Mapping'!E6,120)-1), IF( (AND('(直掃)RX Mapping'!E6>=480,'(直掃)RX Mapping'!E6<=960)), IF(MOD('(直掃)RX Mapping'!E6,120)=0, 120, 240-MOD('(直掃)RX Mapping'!E6,120)),9999))+IF(AND(MOD('(直掃)RX Mapping'!E6,120)=0, '(直掃)RX Mapping'!E6 <= 480, '(直掃)RX Mapping'!E6 > 0), 120) -> 124 | F6: =IF( (AND('(直掃)RX Mapping'!F6>=0,'(直掃)RX Mapping'!F6<=480)), (MOD('(直掃)RX Mapping'!F6,120)-1), IF( (AND('(直掃)RX Mapping'!F6>=480,'(直掃)RX Mapping'!F6<=960)), IF(MOD('(直掃)RX Mapping'!F6,120)=0, 120, 240-MOD('(直掃)RX Mapping'!F6,120)),9999))+IF(AND(MOD('(直掃)RX Mapping'!F6,120)=0, '(直掃)RX Mapping'!F6 <= 480, '(直掃)RX Mapping'!F6 > 0), 120) -> 154 | G6: =IF( (AND('(直掃)RX Mapping'!G6>=0,'(直掃)RX Mapping'!G6<=480)), (MOD('(直掃)RX Mapping'!G6,120)-1), IF( (AND('(直掃)RX Mapping'!G6>=480,'(直掃)RX Mapping'!G6<=960)), IF(MOD('(直掃)RX Mapping'!G6,120)=0, 120, 240-MOD('(直掃)RX Mapping'!G6,120)),9999))+IF(AND(MOD('(直掃)RX Mapping'!G6,120)=0, '(直掃)RX Mapping'!G6 <= 480, '(直掃)RX Mapping'!G6 > 0), 120) -> 184 | H6: =IF( (AND('(直掃)RX Mapping'!H6>=0,'(直掃)RX Mapping'!H6<=480)), (MOD('(直掃)RX Mapping'!H6,120)-1), IF( (AND('(直掃)RX Mapping'!H6>=480,'(直掃)RX Mapping'!H6<=960)), IF(MOD('(直掃)RX Mapping'!H6,120)=0, 120, 240-MOD('(直掃)RX Mapping'!H6,120)),9999))+IF(AND(MOD('(直掃)RX Mapping'!H6,120)=0, '(直掃)RX Mapping'!H6 <= 480, '(直掃)RX Mapping'!H6 > 0), 120) -> 124 | I6: =IF( (AND('(直掃)RX Mapping'!I6>=0,'(直掃)RX Mapping'!I6<=480)), (MOD('(直掃)RX Mapping'!I6,120)-1), IF( (AND('(直掃)RX Mapping'!I6>=480,'(直掃)RX Mapping'!I6<=960)), IF(MOD('(直掃)RX Mapping'!I6,120)=0, 120, 240-MOD('(直掃)RX Mapping'!I6,120)),9999))+IF(AND(MOD('(直掃)RX Mapping'!I6,120)=0, '(直掃)RX Mapping'!I6 <= 480, '(直掃)RX Mapping'!I6 > 0), 120) -> 154 | ... AS6: =IF( (AND('(直掃)RX Mapping'!AS6>=0,'(直掃)RX Mapping'!AS6<=480)), (MOD('(直掃)RX Mapping'!AS6,120)-1), IF( (AND('(直掃)RX Mapping'!AS6>=480,'(直掃)RX Mapping'!AS6<=960)), IF(MOD('(直掃)RX Mapping'!AS6,120)=0, 120, 240-MOD('(直掃)RX Mapping'!AS6,120)),9999))+IF(AND(MOD('(直掃)RX Mapping'!AS6,120)=0, '(直掃)RX Mapping'!AS6 <= 480, '(直掃)RX Mapping'!AS6 > 0), 120) -> -1 | AT6: =IF(AND('(橫掃)RX Mapping'!AT6>=1,'(橫掃)RX Mapping'!AT6<=120), ('(橫掃)RX Mapping'!AT6-1),IF(AND('(橫掃)RX Mapping'!AT6>=121,'(橫掃)RX Mapping'!AT6<=240), (-1)*('(橫掃)RX Mapping'!AT6-240),IF(AND('(橫掃)RX Mapping'!AT6>=241,'(橫掃)RX Mapping'!AT6<=360), ('(橫掃)RX Mapping'!AT6-241),IF(AND('(橫掃)RX Mapping'!AT6>=361,'(橫掃)RX Mapping'!AT6<=480), (-1)*('(橫掃)RX Mapping'!AT6-480),IF(AND('(橫掃)RX Mapping'!AT6>=481,'(橫掃)RX Mapping'!AT6<=600), ('(橫掃)RX Mapping'!AT6-361),IF(AND('(橫掃)RX Mapping'!AT6>=601,'(橫掃)RX Mapping'!AT6<=720), (-1)*('(橫掃)RX Mapping'!AT6-720)+120,IF(AND('(橫掃)RX Mapping'!AT6>=721,'(橫掃)RX Mapping'!AT6<=840), ('(橫掃)RX Mapping'!AT6-601),IF(AND('(橫掃)RX Mapping'!AT6>=841,'(橫掃)RX Mapping'!AT6<=960), (-1)*('(橫掃)RX Mapping'!AT6-960)+120,9999)))))))) -> 9999 | AU6: =IF(AND('(橫掃)RX Mapping'!AU6>=1,'(橫掃)RX Mapping'!AU6<=120), ('(橫掃)RX Mapping'!AU6-1),IF(AND('(橫掃)RX Mapping'!AU6>=121,'(橫掃)RX Mapping'!AU6<=240), (-1)*('(橫掃)RX Mapping'!AU6-240),IF(AND('(橫掃)RX Mapping'!AU6>=241,'(橫掃)RX Mapping'!AU6<=360), ('(橫掃)RX Mapping'!AU6-241),IF(AND('(橫掃)RX Mapping'!AU6>=361,'(橫掃)RX Mapping'!AU6<=480), (-1)*('(橫掃)RX Mapping'!AU6-480),IF(AND('(橫掃)RX Mapping'!AU6>=481,'(橫掃)RX Mapping'!AU6<=600), ('(橫掃)RX Mapping'!AU6-361),IF(AND('(橫掃)RX Mapping'!AU6>=601,'(橫掃)RX Mapping'!AU6<=720), (-1)*('(橫掃)RX Mapping'!AU6-720)+120,IF(AND('(橫掃)RX Mapping'!AU6>=721,'(橫掃)RX Mapping'!AU6<=840), ('(橫掃)RX Mapping'!AU6-601),IF(AND('(橫掃)RX Mapping'!AU6>=841,'(橫掃)RX Mapping'!AU6<=960), (-1)*('(橫掃)RX Mapping'!AU6-960)+120,9999)))))))) -> 9999 | AV6: =IF(AND('(橫掃)RX Mapping'!AV6>=1,'(橫掃)RX Mapping'!AV6<=120), ('(橫掃)RX Mapping'!AV6-1),IF(AND('(橫掃)RX Mapping'!AV6>=121,'(橫掃)RX Mapping'!AV6<=240), (-1)*('(橫掃)RX Mapping'!AV6-240),IF(AND('(橫掃)RX Mapping'!AV6>=241,'(橫掃)RX Mapping'!AV6<=360), ('(橫掃)RX Mapping'!AV6-241),IF(AND('(橫掃)RX Mapping'!AV6>=361,'(橫掃)RX Mapping'!AV6<=480), (-1)*('(橫掃)RX Mapping'!AV6-480),IF(AND('(橫掃)RX Mapping'!AV6>=481,'(橫掃)RX Mapping'!AV6<=600), ('(橫掃)RX Mapping'!AV6-361),IF(AND('(橫掃)RX Mapping'!AV6>=601,'(橫掃)RX Mapping'!AV6<=720), (-1)*('(橫掃)RX Mapping'!AV6-720)+120,IF(AND('(橫掃)RX Mapping'!AV6>=721,'(橫掃)RX Mapping'!AV6<=840), ('(橫掃)RX Mapping'!AV6-601),IF(AND('(橫掃)RX Mapping'!AV6>=841,'(橫掃)RX Mapping'!AV6<=960), (-1)*('(橫掃)RX Mapping'!AV6-960)+120,9999)))))))) -> 9999 | AW6: =IF(AND('(橫掃)RX Mapping'!AW6>=1,'(橫掃)RX Mapping'!AW6<=120), ('(橫掃)RX Mapping'!AW6-1),IF(AND('(橫掃)RX Mapping'!AW6>=121,'(橫掃)RX Mapping'!AW6<=240), (-1)*('(橫掃)RX Mapping'!AW6-240),IF(AND('(橫掃)RX Mapping'!AW6>=241,'(橫掃)RX Mapping'!AW6<=360), ('(橫掃)RX Mapping'!AW6-241),IF(AND('(橫掃)RX Mapping'!AW6>=361,'(橫掃)RX Mapping'!AW6<=480), (-1)*('(橫掃)RX Mapping'!AW6-480),IF(AND('(橫掃)RX Mapping'!AW6>=481,'(橫掃)RX Mapping'!AW6<=600), ('(橫掃)RX Mapping'!AW6-361),IF(AND('(橫掃)RX Mapping'!AW6>=601,'(橫掃)RX Mapping'!AW6<=720), (-1)*('(橫掃)RX Mapping'!AW6-720)+120,IF(AND('(橫掃)RX Mapping'!AW6>=721,'(橫掃)RX Mapping'!AW6<=840), ('(橫掃)RX Mapping'!AW6-601),IF(AND('(橫掃)RX Mapping'!AW6>=841,'(橫掃)RX Mapping'!AW6<=960), (-1)*('(橫掃)RX Mapping'!AW6-960)+120,9999)))))))) -> 9999 | AX6: =IF(AND('(橫掃)RX Mapping'!AX6>=1,'(橫掃)RX Mapping'!AX6<=120), ('(橫掃)RX Mapping'!AX6-1),IF(AND('(橫掃)RX Mapping'!AX6>=121,'(橫掃)RX Mapping'!AX6<=240), (-1)*('(橫掃)RX Mapping'!AX6-240),IF(AND('(橫掃)RX Mapping'!AX6>=241,'(橫掃)RX Mapping'!AX6<=360), ('(橫掃)RX Mapping'!AX6-241),IF(AND('(橫掃)RX Mapping'!AX6>=361,'(橫掃)RX Mapping'!AX6<=480), (-1)*('(橫掃)RX Mapping'!AX6-480),IF(AND('(橫掃)RX Mapping'!AX6>=481,'(橫掃)RX Mapping'!AX6<=600), ('(橫掃)RX Mapping'!AX6-361),IF(AND('(橫掃)RX Mapping'!AX6>=601,'(橫掃)RX Mapping'!AX6<=720), (-1)*('(橫掃)RX Mapping'!AX6-720)+120,IF(AND('(橫掃)RX Mapping'!AX6>=721,'(橫掃)RX Mapping'!AX6<=840), ('(橫掃)RX Mapping'!AX6-601),IF(AND('(橫掃)RX Mapping'!AX6>=841,'(橫掃)RX Mapping'!AX6<=960), (-1)*('(橫掃)RX Mapping'!AX6-960)+120,9999)))))))) -> 9999 | AY6: =IF(AND('(橫掃)RX Mapping'!AY6>=1,'(橫掃)RX Mapping'!AY6<=120), ('(橫掃)RX Mapping'!AY6-1),IF(AND('(橫掃)RX Mapping'!AY6>=121,'(橫掃)RX Mapping'!AY6<=240), (-1)*('(橫掃)RX Mapping'!AY6-240),IF(AND('(橫掃)RX Mapping'!AY6>=241,'(橫掃)RX Mapping'!AY6<=360), ('(橫掃)RX Mapping'!AY6-241),IF(AND('(橫掃)RX Mapping'!AY6>=361,'(橫掃)RX Mapping'!AY6<=480), (-1)*('(橫掃)RX Mapping'!AY6-480),IF(AND('(橫掃)RX Mapping'!AY6>=481,'(橫掃)RX Mapping'!AY6<=600), ('(橫掃)RX Mapping'!AY6-361),IF(AND('(橫掃)RX Mapping'!AY6>=601,'(橫掃)RX Mapping'!AY6<=720), (-1)*('(橫掃)RX Mapping'!AY6-720)+120,IF(AND('(橫掃)RX Mapping'!AY6>=721,'(橫掃)RX Mapping'!AY6<=840), ('(橫掃)RX Mapping'!AY6-601),IF(AND('(橫掃)RX Mapping'!AY6>=841,'(橫掃)RX Mapping'!AY6<=960), (-1)*('(橫掃)RX Mapping'!AY6-960)+120,9999)))))))) -> 9999 | AZ6: =IF(AND('(橫掃)RX Mapping'!AZ6>=1,'(橫掃)RX Mapping'!AZ6<=120), ('(橫掃)RX Mapping'!AZ6-1),IF(AND('(橫掃)RX Mapping'!AZ6>=121,'(橫掃)RX Mapping'!AZ6<=240), (-1)*('(橫掃)RX Mapping'!AZ6-240),IF(AND('(橫掃)RX Mapping'!AZ6>=241,'(橫掃)RX Mapping'!AZ6<=360), ('(橫掃)RX Mapping'!AZ6-241),IF(AND('(橫掃)RX Mapping'!AZ6>=361,'(橫掃)RX Mapping'!AZ6<=480), (-1)*('(橫掃)RX Mapping'!AZ6-480),IF(AND('(橫掃)RX Mapping'!AZ6>=481,'(橫掃)RX Mapping'!AZ6<=600), ('(橫掃)RX Mapping'!AZ6-361),IF(AND('(橫掃)RX Mapping'!AZ6>=601,'(橫掃)RX Mapping'!AZ6<=720), (-1)*('(橫掃)RX Mapping'!AZ6-720)+120,IF(AND('(橫掃)RX Mapping'!AZ6>=721,'(橫掃)RX Mapping'!AZ6<=840), ('(橫掃)RX Mapping'!AZ6-601),IF(AND('(橫掃)RX Mapping'!AZ6>=841,'(橫掃)RX Mapping'!AZ6<=960), (-1)*('(橫掃)RX Mapping'!AZ6-960)+120,9999)))))))) -> 9999 | BA6: =IF(AND('(橫掃)RX Mapping'!BA6>=1,'(橫掃)RX Mapping'!BA6<=120), ('(橫掃)RX Mapping'!BA6-1),IF(AND('(橫掃)RX Mapping'!BA6>=121,'(橫掃)RX Mapping'!BA6<=240), (-1)*('(橫掃)RX Mapping'!BA6-240),IF(AND('(橫掃)RX Mapping'!BA6>=241,'(橫掃)RX Mapping'!BA6<=360), ('(橫掃)RX Mapping'!BA6-241),IF(AND('(橫掃)RX Mapping'!BA6>=361,'(橫掃)RX Mapping'!BA6<=480), (-1)*('(橫掃)RX Mapping'!BA6-480),IF(AND('(橫掃)RX Mapping'!BA6>=481,'(橫掃)RX Mapping'!BA6<=600), ('(橫掃)RX Mapping'!BA6-361),IF(AND('(橫掃)RX Mapping'!BA6>=601,'(橫掃)RX Mapping'!BA6<=720), (-1)*('(橫掃)RX Mapping'!BA6-720)+120,IF(AND('(橫掃)RX Mapping'!BA6>=721,'(橫掃)RX Mapping'!BA6<=840), ('(橫掃)RX Mapping'!BA6-601),IF(AND('(橫掃)RX Mapping'!BA6>=841,'(橫掃)RX Mapping'!BA6<=960), (-1)*('(橫掃)RX Mapping'!BA6-960)+120,9999)))))))) -> 9999 | ... BI6: =IF(AND('(橫掃)RX Mapping'!BI6>=1,'(橫掃)RX Mapping'!BI6<=120), ('(橫掃)RX Mapping'!BI6-1),IF(AND('(橫掃)RX Mapping'!BI6>=121,'(橫掃)RX Mapping'!BI6<=240), (-1)*('(橫掃)RX Mapping'!BI6-240),IF(AND('(橫掃)RX Mapping'!BI6>=241,'(橫掃)RX Mapping'!BI6<=360), ('(橫掃)RX Mapping'!BI6-241),IF(AND('(橫掃)RX Mapping'!BI6>=361,'(橫掃)RX Mapping'!BI6<=480), (-1)*('(橫掃)RX Mapping'!BI6-480),IF(AND('(橫掃)RX Mapping'!BI6>=481,'(橫掃)RX Mapping'!BI6<=600), ('(橫掃)RX Mapping'!BI6-361),IF(AND('(橫掃)RX Mapping'!BI6>=601,'(橫掃)RX Mapping'!BI6<=720), (-1)*('(橫掃)RX Mapping'!BI6-720)+120,IF(AND('(橫掃)RX Mapping'!BI6>=721,'(橫掃)RX Mapping'!BI6<=840), ('(橫掃)RX Mapping'!BI6-601),IF(AND('(橫掃)RX Mapping'!BI6>=841,'(橫掃)RX Mapping'!BI6<=960), (-1)*('(橫掃)RX Mapping'!BI6-960)+120,9999)))))))) -> 9999
